Workbook

Sheet Consolidado-Equipes
H2: 1º Turno | I2: 2º Turno | K2: 3º Turno
B3: Nome | C3: Celular | D3: Atuação | E3: Gestor | F3: Tel Gestor | G3: Local | H3: 07/02 12h50 às 19h | I3: 07/02 19h até 00h | J3: 08/02 00h até 09h | K3: 08/02 08h até 22h30
B4: Jaciara Bomfim | C4: (61) 98626-8685 | D4: Planej Infra TI | E4: Romulo(férias)/Sidney | F4: (11) 97631-2301 | G4: Casa do Ator
B5: Thasio Santos Fazendeiro | C5: (31) 97501-9451 | D5: Planej Infra TI | E5: Romulo(férias)/Sidney | F5: (11) 97631-2301 | G5: Remoto BH
B6: Renato De Assis Vieira | C6: (31) 98207-8920 | D6: Planej Infra TI | E6: Romulo(férias)/Sidney | F6: (11) 97631-2301 | G6: Remoto BH | J6: A partir das 02h
B7: Luciana Franco | C7: (31) 98957-9561 | D7: Planej Infra TI | E7: Romulo(férias)/Sidney | F7: (11) 97631-2301 | G7: Remoto BH
B8: Filipe Goncalves Lima | C8: (61) 98628-3620 | D8: Planej Infra TI | E8: Romulo(férias)/Sidney | F8: (11) 97631-2301 | G8: Remoto DF
B9: Marina Maia Herejk | C9: (61) 98595-2891 | D9: Planej Infra TI | E9: Romulo(férias)/Sidney | F9: (11) 97631-2301 | G9: Remoto DF
B10: Gabriela Chiogna | C10: (61) 98401-1245 | D10: Planej Infra TI | E10: Romulo(férias)/Sidney | F10: (11) 97631-2301 | G10: Remoto DF
B11: Renato Fontes | C11: (31) 98834-3321 | D11: Planej Infra TI | E11: Romulo(férias)/Sidney | F11: (11) 97631-2301 | G11: Remoto BH
B12: Patricia Viturino | C12: (61) 98401-8467 | D12: Planej Infra TI | E12: Romulo(férias)/Sidney | F12: (11) 97631-2301 | G12: Remoto DF | I12: 22h-8h (até 8/fev)
B13: Alex Barcelos | C13: (61) 98596-4456 | D13: Backup | E13: Joel | F13: (11) 98486-9677 | G13: Remoto DF
B14: Rafael Sousa | C14: (61) 98497-4792 | D14: Backup | E14: Joel | F14: (11) 98486-9677 | G14: Remoto DF
B15: Emidio Macedo | C15: (31) 98894-7106 | D15: Storage | E15: Joel | F15: (11) 98486-9677 | G15: Remoto BH | I15: A partir das 22h
B16: Marcos Rocha | C16: (21) 98713-2928 | D16: Linux | E16: Joel | F16: (11) 98486-9677 | G16: Remoto RJ
B17: Sergio Novaes | C17: (31) 98801-0188 | D17: Storage / Linux | E17: Joel | F17: (11) 98486-9677 | G17: Remoto BH
B18: Frederico Crepaldi | C18: (31) 98758-6334 | D18: Linux / VMware | E18: Joel | F18: (11) 98486-9677 | G18: Remoto BH
B19: Leonardo Prates | C19: (11) 98623-8827 | D19: VMware / Windows | E19: Joel | F19: (11) 98486-9677 | G19: Casa do Ator
B20: Gladyston Ribeiro | C20: (31) 98877-9940 | D20: Windows | E20: Joel | F20: (11) 98486-9677 | G20: Remoto BH
B21: Gabriel Pereira | C21: (11) 97339-7530 | D21: SAP | E21: Ewerson | F21: (11) 98337-6112 | G21: Remoto
B22: Roberto Rebeque | C22: (21) 98834-3136 | D22: Corporativos | E22: Ewerson | F22: (11) 98337-6112 | G22: Remoto
B23: Willian De Carvalho Braga | C23: (22) 99896-9630 / (21) 96525-8412 | D23: SAP | E23: Ewerson | F23: (11) 98337-6112 | G23: Remoto
B24: Diogo Fogaca Pereira | C24: (21) 98626-0020 | D24: Corporativos | E24: Ewerson | F24: (11) 98337-6112 | G24: Remoto
B25: Rodrigo De Souza Carvalho | C25: (21) 98559-5762 | D25: SAP | E25: Ewerson | F25: (11) 98337-6112 | G25: Remoto
B26: Roberto Cesar Bezerra Da Maia | C26: (61) 98427-5240 | D26: Control_M | E26: Ewerson | F26: (11) 98337-6112 | G26: Remoto
B27: Silas De Oliveira Cardoso | C27: (61) 9844-91418 | D27: Control_M | E27: Ewerson | F27: (11) 98337-6112 | G27: Remoto
B28: Alexandre Akio | C28: (31) 98783-8391 | D28: Monitoracao | E28: Carlos Eduardo | F28: (11) 94564-7581 | G28: Remoto
B29: Jose Francisco Klaus | C29: (48) 99988-0876 | D29: Monitoracao | E29: Carlos Eduardo | F29: (11) 94564-7581 | G29: Remoto | I29: 22h-8h
B30: Jose Wilamis Silva | C30: (61) 98513-9188 | D30: Monitoracao | E30: Carlos Eduardo | F30: (11) 94564-7581 | G30: Remoto
B31: Rafael Soare Bem Dembicki | C31: (41) 99145-3635 | D31: CMDB | E31: Carlos Eduardo | F31: (11) 94564-7581 | G31: Remoto | I31: 22h-22h30 (até 8/fev)
B32: Tassio da Silva Costa | C32: (61) 98618-0128 | D32: ITSM | E32: Carlos Eduardo | F32: (11) 94564-7581 | G32: Remoto | I32: 22h-8h
B33: Israel Alexandre De Padua Vaz | C33: (61) 98501-4306 | D33: ITSM | E33: Carlos Eduardo | F33: (11) 94564-7581 | G33: Remoto
B34: Frederick William Borges Pohl | C34: (31) 98852-4355 | D34: Redes | E34: Bruno | F34: (11) 99639-6735 | G34: Local ARCOS | I34: 19h-09h
B35: Jose Geraldo Coelho Furtado | C35: (31) 98773-7542 | D35: SRE | E35: Bruno | F35: (11) 99639-6735 | G35: Remoto BH
B36: Christian de Paula Britto Carvalho | C36: (31) 98872-9857 | D36: Banco Dados | E36: Bruno | F36: (11) 99639-6735 | G36: Remoto BH | I36: 20h
B37: Marcos Vinicius Gabriel De Souza | C37: (11) 94077-9197 | D37: Redes | E37: Bruno | F37: (11) 99639-6735
B38: Jose Alberto Afonso Dos Santos | C38: (21) 97686-6049 | D38: Redes | E38: Bruno | F38: (11) 99639-6735
B39: Brenda Agatha Batista Barros | C39: (31) 99185-8886 | D39: SRE | E39: Bruno | F39: (11) 99639-6735 | G39: Remoto BH
B40: Ed Flavio Confessor | C40: (11) 98747-0919 | D40: Banco Dados | E40: Bruno | F40: (11) 99639-6735 | G40: Remoto SP
B41: Luiz Felipe Vieira Puntel | C41: (31) 98758-7194 | D41: Banco Dados | E41: Bruno | F41: (11) 99639-6735 | G41: Remoto BH
...

Sheet Visao executiva

Sheet Ordem Disp Aplicações e Validaç
A1: Ordem de prioridade de disponibilidade. | I1: Validação MS Openshift
A2: Prioridade | B2: Sistema | C2: Parar? | D2: Ambiente | I2: Openshift | J2: Responsável - Janela 19:00 às 09:00
A3: 1 | B3: NETWIN | D3: On-Premise | I3: chinesewall-ms-work-order-management-prod | J3: Jefferson Leite
A4: 2 | B4: SIS ATIVACAO | C4: Sim | D4: On-Premise/Openshift | I4: sis-ativacao-prod | J4: Arsenio Jesus
A5: 3 | B5: SOA | C5: Sim | D5: On-Premise | I5: chinesewall-ms-orderentry-prod | J5: Jefferson Leite
A6: 4 | B6: SOM | C6: Sim | D6: On-Premise | I6: chinesewall-ms-productordering-prod | J6: Jefferson Leite
A7: 5 | B7: OMR | C7: Sim | D7: On-Premise | I7: geosite-admin-prod | J7: Jefferson Leite
A8: 6 | B8: APIGEE | D8: Nuvem | I8: geosite-cgr-prod | J8: Jefferson Leite
A9: 7 | B9: MICROSSERVIÇOS | D9: Openshift (+30 MS) | I9: geosite-cobertura-prod | J9: Jefferson Leite
A10: 8 | B10: GEOSITE LOGRADOURO | D10: Openshift | I10: geosite-logradouros-prod | J10: Jefferson Leite
A11: 9 | B11: PORTAL OPERACIONAL | C11: Sim | D11: Openshift | I11: geosite-mub-prod | J11: Jefferson Leite
A12: 10 | B12: SMART DESK | D12: Nuvem | I12: geosite-proxy-prod | J12: Jefferson Leite
A13: 11 | B13: NETQ | C13: Sim | D13: On-Premise | I13: geosite-rede-prod | J13: Jefferson Leite
A14: 12 | B14: DATA ANALYTICS (GCP) | C14: Sim | D14: Nuvem | I14: geosite-ws-prod | J14: Jefferson Leite
A15: 14 | B15: CO-DIGITAL | D15: On-Premise | I15: microservicososs-fuzzy-viability-check-prod | J15: Jefferson Leite
A16: 15 | B16: ANTECIPA | D16: On-Premise | I16: chinesewall-gestao-servico-prod | J16: Jefferson Leite
A17: 16 | B17: OPM_FSL | D17: On-Premise | I17: chinesewall-ms-communication-bot-prod | J17: Marcio Dourado
A18: 17 | B18: GESTECH | D18: On-Premise | I18: chinesewall-portaloperacional-prod | J18: Michael Douglas
A19: 18 | B19: COLMEIA | D19: Nuvem | I19: inesewall-ms-portalbackend-prod | J19: Michael Douglas
A20: 19 | B20: BOT TROCA DE CDOE | D20: ? | I20: chinesewall-portaldev-frontend-prod | J20: Michael Douglas
A21: 20 | B21: FSL | D21: Nuvem | I21: microservicososs-cgnat-prod | J21: Michael Douglas
A22: 21 | B22: CRE | D22: On-Premise | I22: microservicososs-cobranca-prod | J22: Michael Douglas
A23: 22 | B23: MULESOFT | D23: Nuvem | I23: chinesewall-ms-communication-prod | J23: Sandro Gontijo
A24: 23 | B24: OFS TOA | D24: Nuvem | I24: chinesewall-ms-troubleticket-prod | J24: Sandro Gontijo
A25: 24 | B25: PEGA EVENTOS | D25: Nuvem | I25: chinesewall-ms-appointment-prod | J25: Sandro Gontijo
A26: 25 | B26: PEGA ATACADO | D26: Nuvem | I26: chinesewall-ms-notification-dispatch-prod | J26: Sandro Gontijo
... A31: 30 | B31: NETWORKS CORE | D31: On-Premise | I31: microservicososs-eventmanagement-prod | J31: Sandro Gontijo
A32: 31 | B32: MAESTRO | D32: Nuvem | E32: *Pedir validação do HORIZON ao time de Windows | I32: microservicososs-vtal-aprovisionador-integracoes-prod | J32: Sandro Gontijo
A33: 32 | B33: SAP Globenet | D33: Nuvem | I33: microservicososs-vtal-consulta-ordem-voo-prod | J33: Sandro Gontijo
A34: 33 | B34: SAP Concur Vtal | D34: Nuvem | I34: chinesewall-apihub-frontend-prod | J34: Sandro Gontijo
A35: 34 | B35: SYMSUPPLY | D35: Nuvem | I35: microservicososs-reatribuicao-tech-prod | J35: Sandro Gontijo
A36: 35 | B36: GED 360 | D36: Nuvem | I36: MS - FIBRA ON
A37: 36 | B37: DFE-MasterSAF | D37: Nuvem
A38: 37 | B38: Tax One | D38: Nuvem
A39: 38 | B39: Totvs RM | D39: Nuvem
A40: 39 | B40: BMC Control | D40: Nuvem
A41: 13 | B41: JETL | D41: On-Premise | I41: FÁBRICAS e N3
A42: 40 | B42: SAP Concur GB Net | D42: Nuvem | I42: Bruno Lincoln | J42: (31) 99922-1388 | K42: OPENSHIFT
A43: 41 | B43: NEXXERA | D43: On-Premise | I43: Felipe Alves | J43: (61) 98408-3707 | K43: OMR- WORKFLOW
A44: 42 | B44: Coupa | D44: Nuvem | I44: Renata Rodrigues | J44: (21) 98832-5738 | K44: API/SOA/MS
...

Sheet CRQ34495 - REDE2
A1: Seq | B1: Atividade | C1: Grupo | D1: Localidade | E1: Executor | F1: Telefone | G1: Inicio | H1: Fim | I1: Tempo | J1: Status
A2: 5 | B2: INÍCIO CRQ | C2: IMPLANTACAOINFRATI_N2 | D2: REMOTO / BH | E2: RENATO D VIEIRA | F2: 31 98207-8920 | G2: 46060.535 | H2: =G2+I2 -> 46060.542 | I2: 0.0069444444 | J2: Concluído
A3: 10 | B3: VALIDAÇÃO BACKUP DOS ICS RELACIONADOS | C3: BACKUPPLANEJAMENTO_N2 | D3: REMOTO / DF | E3: RAFAEL SOUSA | F3: 61 98497-4792 | G3: =H2 -> 46060.542 | H3: =G3+I3 -> 46060.708 | I3: 0.16666667 | J3: Em execução no prazo | L3: Rótulos de Linha | M3: Contagem de Atividade
A4: 15 | B4: STOP DOS JOBS E CADEIAS CONTROL-M PRODUÇÃO | C4: PCP_N2 | D4: REMOTO / DF | E4: SILAS DE OLIVEIRA | F4: 61 9844-91418 | G4: =H3 -> 46060.708 | H4: =G4+I4 -> 46060.75 | I4: 0.041666667 | J4: A Iniciar no prazo | L4: A Iniciar no prazo | M4: 73
A5: 15 | B5: STOP DOS JOBS E CADEIAS CONTROL-M BACKUP | C5: BACKUPPLANEJAMENTO_N2 | D5: REMOTO / DF | E5: RAFAEL SOUSA | F5: 61 98497-4792 | G5: =H3 -> 46060.708 | H5: =G5+I5 -> 46060.75 | I5: 0.041666667 | J5: A Iniciar no prazo | L5: N/A | M5: 5
A6: 18 | B6: REALIZAR BACKUP DOS ELEMENTOS DE REDE | C6: REDES | D6: PRESENCIAL / RJ | E6: FRED POLH | F6: 31 98852-4355 | G6: =H5 -> 46060.75 | H6: =G6+I6 -> 46060.792 | I6: 0.041666667 | J6: A Iniciar no prazo | L6: Total Geral | M6: 78
A7: 18 | B7: STOP DA APLICAÇÃO SOM/OMR | C7: SOM_N2 | D7: REMOTO / DF | E7: DIONEY YANO | F7: 61 98466-4590 | G7: =H6 -> 46060.792 | H7: =G7+I7 -> 46060.833 | I7: 0.041666667 | J7: A Iniciar no prazo
A8: 19 | B8: STOP DA APLICAÇÃO SIS ATIVAÇÃO/NETQ (tudo menos openshift) | C8: SISATIVACAOFIXA_N2 | D8: REMOTO / DF | E8: ARSENIO SANTOS | F8: 61 98665-4644 | G8: =H6 -> 46060.792 | H8: =G8+I8 -> 46060.833 | I8: 0.041666667 | J8: A Iniciar no prazo
A9: 19 | B9: STOP DA APLICAÇÃO SOA | C9: INTEGRACAO_N2 | D9: REMOTO / DF | E9: GRIGORIO | F9: 6198402-4853 | G9: =H6 -> 46060.792 | H9: =G9+I9 -> 46060.833 | I9: 0.041666667 | J9: A Iniciar no prazo
A10: 19 | B10: STOP DA APLICAÇÃO NETWIN | C10: NETWIN_N2 | D10: REMOTO / DF | E10: DANIEL PRAXEDES | F10: 61 98491-6039 | G10: =H6 -> 46060.792 | H10: =G10+I10 -> 46060.833 | I10: 0.041666667 | J10: A Iniciar no prazo
A11: 19 | B11: STOP DA APLICAÇÃO GCP | C11: JORNADAL2O_N2 | D11: REMOTO / RJ | E11: PAULO PIMENTA | F11: 21987375200 | G11: =H6 -> 46060.792 | H11: =G11+I11 -> 46060.833 | I11: 0.041666667 | J11: A Iniciar no prazo
A12: 19 | B12: STOP GESTECH | C12: JORNADAFULF_N2 | E12: DANIEL FAZION | G12: =H6 -> 46060.792 | H12: =G12+I12 -> 46060.833 | I12: 0.041666667 | J12: A Iniciar no prazo
A13: 20 | B13: STOP DO BDs e GRID que NÃO serão migrados das aplicações acima | C13: ORACLE_N2 | D13: REMOTO /BH | E13: CHRISTIAN | F13: (31) 98872-9857 | G13: =H11 -> 46060.833 | H13: =G13+I13 -> 46060.917 | I13: 0.083333333 | J13: A Iniciar no prazo
A14: 19 | B14: CRQ SI | D14: REMOTO / DF | E14: ALAN BREGUES | F14: 61 98574-9927 | G14: ='[1]CRQ33459 - SI2'!G6 -> 46060.792 | H14: ='[1]CRQ33459 - SI2'!H13 -> 46060.958 | J14: N/A
A15: 19 | B15: CRQ Openshift | D15: REMOTO / BH | E15: RENATO D VIEIRA | F15: 31 98207-8920 | G15: ='[1]CRQ033493 - OPENSHIFT2'!G6 -> 46060.792 | H15: ='[1]CRQ033493 - OPENSHIFT2'!H12 -> 46060.958 | J15: N/A
A16: 19 | B16: CRQ NAS | D16: REMOTO / DF | E16: FILIPE LIMA | F16: 61 98628-3620 | G16: ='[1]CRQ34463 - NFS2'!G2 -> 46060.785 | H16: ='CRQ34494 - NFS2'!H5 -> 46060.958 | J16: N/A
A17: BO | B17: REALIZAR MIGRAÇÃO DA VLANS PARA O DC ARCOS | C17: REDES | D17: PRESENCIAL / RJ | E17: FRED POLH | F17: 31 98852-4355 | G17: =H14 -> 46060.958 | H17: =G17+I17 -> 46061.073 | I17: 0.11458333 | J17: A Iniciar no prazo
A18: 27 | B18: START DOS BDs .....(add as outras aplicações) | C18: ORACLE_N2 | D18: REMOTO / BH | E18: CHRISTIAN | F18: (31) 98872-9857 | G18: =H17 -> 46061.073 | H18: =G18+I18 -> 46061.115 | I18: 0.041666667 | J18: A Iniciar no prazo
A19: 27 | B19: VALIDAR TODAS as outras aplicações | C19: JORNADAFULF_N2 | D19: REMOTO / DF | E19: DIEGO ARCANJO | F19: 61 98679-4930 | G19: =H17 -> 46061.073 | H19: =G19+I19 -> 46061.115 | I19: 0.041666667 | J19: A Iniciar no prazo
A20: 27 | B20: VALIDAR TODAS as outras aplicações | C20: JORNADAL2O_N2 | D20: REMOTO / DF | E20: MARCIO ROBERTO | F20: 61 98409-4671 | G20: =H17 -> 46061.073 | H20: =G20+I20 -> 46061.115 | I20: 0.041666667 | J20: A Iniciar no prazo
A21: 27 | B21: VALIDAR TODAS aplicações (Ewerson) | C21: JORNADACORP_N2 | D21: REMOTO / RJ | E21: ROBERTO REBEQUE | F21: 21 98834-3136 | G21: =H17 -> 46061.073 | H21: =G21+I21 -> 46061.115 | I21: 0.041666667 | J21: A Iniciar no prazo
A22: 27 | B22: VALIDAR ITSM | C22: ITSM_N2 | D22: REMOTO / DF | E22: TASSIO COSTA | F22: 61 98618-0128 | G22: =H17 -> 46061.073 | H22: =G22+I22 -> 46061.115 | I22: 0.041666667 | J22: A Iniciar no prazo
A23: 27 | B23: VALIDAR Monitoração | C23: MONITORACAO_N2 | D23: REMOTO / TO | E23: JOSE FRANCISCO KLAUS | F23: 48 99988-0876 | G23: =H17 -> 46061.073 | H23: =G23+I23 -> 46061.115 | I23: 0.041666667 | J23: A Iniciar no prazo
A24: 27 | B24: VALIDAR CMDB | C24: CMDB_N2 | D24: REMOTO / PR | E24: RAFAEL DEMBICKI | F24: 41 99145- 3635 | G24: =H17 -> 46061.073 | H24: =G24+I24 -> 46061.115 | I24: 0.041666667 | J24: A Iniciar no prazo
A25: 27 | B25: VALIDAR aplicações SI | C25: IDDIGITAL_N2 | D25: REMOTO / DF | E25: ALAN BREGUES | F25: 61 985749927 | G25: =H17 -> 46061.073 | H25: =G25+I25 -> 46061.115 | I25: 0.041666667 | J25: A Iniciar no prazo
A26: 27 | B26: VALIDAR aplicações SI (COPS) | C26: SOC_N2 | D26: REMOTO / RJ | E26: MARCELO MONTEZUMA | F26: 21 98864-0464 | G26: =H17 -> 46061.073 | H26: =G26+I26 -> 46061.115 | I26: 0.041666667 | J26: A Iniciar no prazo
A27: 27 | B27: START e VALIDAÇÃO GESTECH | C27: JORNADAFULF_N2 | E27: DANIEL FAZION | G27: =H17 -> 46061.073 | H27: =G27+I27 -> 46061.156 | I27: 0.083333333 | J27: A Iniciar no prazo
A28: 28 | B28: START DA APLICAÇÃO SIS ATIVAÇÃO/ NETQ (tudo menos openshift) | C28: SISATIVACAOFIXA_N2 | D28: REMOTO / DF | E28: ARSENIO SANTOS | F28: 61 98665-4644 | G28: =H18 -> 46061.115 | H28: =G28+I28 -> 46061.156 | I28: 0.041666667 | J28: A Iniciar no prazo
A29: 28 | B29: START DA APLICAÇÃO SOA | C29: INTEGRACAO_N2 | D29: REMOTO / DF | E29: GRIGORIO | F29: 61984024853 | G29: =H18 -> 46061.115 | H29: =G29+I29 -> 46061.156 | I29: 0.041666667 | J29: A Iniciar no prazo
A30: 28 | B30: START DA APLICAÇÃO NETWIN | C30: NETWIN_N2 | D30: REMOTO / DF | E30: DANIEL PRAXEDES | F30: 61 98491-6039 | G30: =H18 -> 46061.115 | H30: =G30+I30 -> 46061.156 | I30: 0.041666667 | J30: A Iniciar no prazo
A31: 28 | B31: START DA APLICAÇÃO GCP | C31: JORNADAL2O_N2 | D31: REMOTO / RJ | E31: PAULO PIMENTA | F31: 21987375200 | G31: =H18 -> 46061.115 | H31: =G31+I31 -> 46061.156 | I31: 0.041666667 | J31: A Iniciar no prazo
A32: 28 | B32: VALIDAR TODAS as outras aplicações | C32: JORNADAFULF_N2 | D32: REMOTO / DF | E32: DIEGO ARCANJO | F32: 61 98679-4930 | G32: =H26 -> 46061.115 | H32: =G32+I32 -> 46061.156 | I32: 0.041666667 | J32: A Iniciar no prazo
A33: 28 | B33: VALIDAR TODAS as outras aplicações | C33: JORNADAL2O_N2 | D33: REMOTO / DF | E33: MARCIO ROBERTO | F33: 61 98409-4671 | G33: =H26 -> 46061.115 | H33: =G33+I33 -> 46061.156 | I33: 0.041666667 | J33: A Iniciar no prazo
A34: 28 | B34: VALIDAR Monitoração | C34: MONITORACAO_N2 | D34: REMOTO / TO | E34: JOSE FRANCISCO KLAUS | F34: 48 99988-0876 | G34: =H26 -> 46061.115 | H34: =G34+I34 -> 46061.156 | I34: 0.041666667 | J34: A Iniciar no prazo
A35: 28 | B35: VALIDAR CMDB | C35: CMDB_N2 | D35: REMOTO / PR | E35: RAFAEL DEMBICKI | F35: 41 99145- 3635 | G35: =H26 -> 46061.115 | H35: =G35+I35 -> 46061.156 | I35: 0.041666667 | J35: A Iniciar no prazo
A36: 28 | B36: VALIDAR aplicações SI | C36: IDDIGITAL_N2 | D36: REMOTO / DF | E36: ROMANO GOMES | F36: 61 985749927 | G36: =H26 -> 46061.115 | H36: =G36+I36 -> 46061.156 | I36: 0.041666667 | J36: A Iniciar no prazo
A37: 29 | B37: START DA APLICAÇÃO SOM/OMR | C37: SOM_N2 | D37: REMOTO / DF | E37: DIONEY YANO | F37: 61 98466-4590 | G37: =H30 -> 46061.156 | H37: =G37+I37 -> 46061.198 | I37: 0.041666667 | J37: A Iniciar no prazo
A38: 30 | B38: VALIDAR APLICAÇÃO SIS ATIVAÇÃO/NETQ | C38: SISATIVACAOFIXA_N2 | D38: REMOTO / DF | E38: ARSENIO SANTOS | F38: 61 98665-4644 | G38: =H37 -> 46061.198 | H38: =G38+I38 -> 46061.281 | I38: 0.083333333 | J38: A Iniciar no prazo
A39: 30 | B39: VALIDAR SOA | C39: INTEGRACAO_N2 | D39: REMOTO / DF | E39: GRIGORIO | F39: 61984024853 | G39: =H37 -> 46061.198 | H39: =G39+I39 -> 46061.281 | I39: 0.083333333 | J39: A Iniciar no prazo
A40: 30 | B40: VALIDAR NETWIN | C40: NETWIN_N2 | D40: REMOTO / DF | E40: DANIEL PRAXEDES | F40: 61 98491-6039 | G40: =H37 -> 46061.198 | H40: =G40+I40 -> 46061.281 | I40: 0.083333333 | J40: A Iniciar no prazo
...

Sheet CRQ34512 - OPENSHIFT2
A1: Seq | B1: Atividade | C1: Grupo | D1: localidade | E1: Executor | F1: Telefone | G1: Inicio | H1: Fim | I1: Tempo | J1: Status | L1: PORTAL OPERACIONAL - PCW - PRD
A2: 5 | B2: INÍCIO CRQ | C2: IMPLANTACAOINFRATI_N2 | D2: REMOTO / BH | E2: RENATO VIEIRA | F2: 31 97501-9451 | G2: 46060.701 | H2: =G2+I2 -> 46060.708 | I2: 0.0069444444 | J2: A Iniciar no prazo | L2: [VTAL] GEOSITE - PRD
A3: 10 | B3: BACKUP FULL DOS ICS RELACIONADOS | C3: BACKUPPLANEJAMENTO_N2 | D3: REMOTO / DF | E3: ALEX B SOARES | F3: 61 98596-4456 | G3: =H2 -> 46060.708 | H3: =G3+I3 -> 46060.75 | I3: 0.041666667 | J3: A Iniciar no prazo | L3: GEOSITE LOGRADOURO - PRD | N3: Rótulos de Linha | O3: Total
A4: 15 | B4: STOP DOS JOBS E CADEIAS CONTROL-M | C4: PCP_N2 | D4: REMOTO / DF | E4: SILAS DE OLIVEIRA | F4: 61 9844-91418 | G4: =H3 -> 46060.75 | H4: =G4+I4 -> 46060.792 | I4: 0.041666667 | J4: A Iniciar no prazo | L4: MICROSSERVICOS CW - PRD | N4: A Iniciar no prazo | O4: 32
A5: 15 | B5: STOP DAS ROTINAS DE BACKUP E JOBS CONTROL-M | C5: BACKUPPLANEJAMENTO_N2 | D5: REMOTO / DF | E5: ALEX B SOARES | F5: 61 98596-4456 | G5: =H3 -> 46060.75 | H5: =G5+I5 -> 46060.792 | I5: 0.041666667 | J5: A Iniciar no prazo | L5: MS ORDER ENTRY - PRD | N5: N/A | O5: 2
A6: 18 | B6: PARAR APLICAÇÕES (ARCOS E SCN PRD) | C6: INFRADIGITAL_N2 | D6: REMOTO / BH | E6: JOSE GERALDO | F6: 31 98773-7542 | G6: 46060.792 | H6: =G6+I6 -> 46060.854 | I6: 0.0625 | J6: A Iniciar no prazo | L6: MS-COBRANÇA - PRD + MSCGNAT (Openshift) | N6: Total Geral | O6: 34
A7: 20 | B7: CONFIGURAÇÕES DO DNS/ROTAS OPENSHIFT | C7: INFRADIGITAL_N2 | D7: REMOTO / BH | E7: JOSE GERALDO | F7: 31 98773-7542 | G7: =H6 -> 46060.854 | H7: =G7+I7 -> 46060.917 | I7: 0.0625 | J7: A Iniciar no prazo | L7: ms-fuzzy-availability-check - PRD
A8: 20 | B8: AJUSTAR ALIAS DNS PARA OS NOVOS SERVIDORES | C8: WINDOWS_N2 | D8: REMOTO / BH | E8: GLADYSTON | F8: 31 98877-9940 | G8: =H6 -> 46060.854 | H8: =G8+I8 -> 46060.917 | I8: 0.0625 | J8: A Iniciar no prazo
A9: 20 | B9: EXECUTAR VIRADA DE PRODUÇÃO PARA ARCOS | C9: ORACLE_N2 | D9: REMOTO / BH | E9: CHRISTIAN | F9: 31 98872-9857 | G9: =H6 -> 46060.854 | H9: =G9+I9 -> 46060.917 | I9: 0.0625 | J9: A Iniciar no prazo | L9: Incluir os nomes dos BDs a serem migrados
A10: 20 | B10: MIGRAÇÃO DOS ICS RELACIONADOS | C10: UNIX_N2 | D10: REMOTO / BH | E10: FREDERICO M CREPALDI | F10: 31 98758-6334 | G10: =H6 -> 46060.854 | H10: =G10+I10 -> 46060.917 | I10: 0.0625 | J10: A Iniciar no prazo
A11: 20 | B11: MONITORAR GUARDICORE NOS SERVIDORES | C11: SEGSDI_N2 | D11: REMOTO / SP | E11: TIAGO FERREIRA CAMPOS | F11: 11 98268-7112 | G11: =H6 -> 46060.854 | H11: =G11+I11 -> 46060.917 | I11: 0.0625 | J11: A Iniciar no prazo
A12: 25 | B12: STOP dos BDs | C12: ORACLE_N2 | D12: REMOTO / BH | E12: CHRISTIAN | F12: 31 98872-9857 | G12: =H8 -> 46060.917 | H12: =G12+I12 -> 46060.958 | I12: 0.041666667 | J12: A Iniciar no prazo | L12: Incluir os nomes dos BDs a serem migrados
B13: CRQ NFS | D13: REMOTO / DF | E13: FILIPE LIMA | F13: 61 98628-3620 | G13: =H6 -> 46060.854 | H13: =H14 -> 46061.073 | I13: 0.125 | J13: N/A
B14: VIRADA da REDE | D14: PRESENCIAL / RJ | E14: FRED POLH | F14: 31 98852-4355 | G14: ='[1]CRQ34373 - REDE2'!G17 -> 46060.958 | H14: ='[1]CRQ34373 - REDE2'!H17 -> 46061.073 | J14: N/A
A15: 26 | B15: REMOÇÃO DOS PVCS APONTANDO PARA O ANTIGO NFS | C15: INFRADIGITAL_N2 | D15: REMOTO / BH | E15: JOSE GERALDO | F15: 31 98773-7542 | G15: =H14 -> 46061.073 | H15: =G15+I15 -> 46061.115 | I15: 0.041666667 | J15: A Iniciar no prazo
A16: 26 | B16: CRIAÇÃO DOS PVCS APONTANDO PARA O NOVO NFS | C16: INFRADIGITAL_N2 | D16: REMOTO / BH | E16: JOSE GERALDO | F16: 31 98773-7542 | G16: =H14 -> 46061.073 | H16: =G16+I16 -> 46061.115 | I16: 0.041666667 | J16: A Iniciar no prazo
A17: 27 | B17: START SERVIDORES SATÉLITES (ELK, REDIS, APACHE INTERNO E DMZ) | C17: JORNADAL2O_N2 | E17: JEFFERSON LEITE | F17: 61 986558588 | G17: =H16 -> 46061.115 | H17: =G17+I17 -> 46061.156 | I17: 0.041666667 | J17: A Iniciar no prazo
A18: 28 | B18: SUBIR APLICAÇÃO (ARCOS PRD) DOS MICROSERVIÇOS | C18: INFRADIGITAL_N2 | D18: REMOTO / BH | E18: JOSE GERALDO | F18: 31 98773-7542 | G18: =H17 -> 46061.156 | H18: =G18+I18 -> 46061.229 | I18: 0.072916667 | J18: A Iniciar no prazo
A19: 30 | B19: VALIDAR APLICAÇÃO | C19: JORNADAL2O_N2 | D19: REMOTO / RJ | E19: JEFFERSON LEITE | F19: 61 986558588 | G19: =H18 -> 46061.229 | H19: =G19+I19 -> 46061.396 | I19: 0.16666667 | J19: A Iniciar no prazo
A20: 30 | B20: VALIDAR APLICAÇÃO | C20: JORNADAFULF_N2 | D20: REMOTO / SP | E20: MICHAEL D SILVA | F20: 19 98349-4052 | G20: =H18 -> 46061.229 | H20: =G20+I20 -> 46061.396 | I20: 0.16666667 | J20: A Iniciar no prazo
A21: 30 | B21: VALIDAR APLICAÇÃO PELA ÁREA USUÁRIA | E21: ??? | G21: =H18 -> 46061.229 | H21: =G21+I21 -> 46061.396 | I21: 0.16666667 | J21: A Iniciar no prazo
A22: 35 | B22: LIBERAR ROTINAS DE BACKUP E JOBS CONTROL-M | C22: BACKUPPLANEJAMENTO_N2 | D22: REMOTO / DF | E22: RAFAEL SOUSA | F22: 61 98497-4792 | G22: =H21 -> 46061.396 | H22: =G22+I22 -> 46061.437 | I22: 0.041666667 | J22: A Iniciar no prazo
A23: 35 | B23: RETIRAR DE HOLD JOBS E CADEIAS CONTROL-M | C23: PCP_N2 | D23: REMOTO / DF | E23: ROBERTO MAIA | F23: 61 98427-5240 | G23: =H21 -> 46061.396 | H23: =G23+I23 -> 46061.437 | I23: 0.041666667 | J23: A Iniciar no prazo
A24: ROLLBACK | J24: N/A
A25: 38 | B25: ATIVIDADE DE ROLLBACK - PARAR APLICAÇÃO | C25: INFRADIGITAL_N2 | D25: REMOTO / BH | E25: JOSE GERALDO | F25: 31 98773-7542 | G25: =H21 -> 46061.396 | H25: =G25+I25 -> 46061.437 | I25: 0.041666667 | J25: A Iniciar no prazo
A26: 45 | B26: CONFIGURAÇÕES DO DNS/ROTAS OPENSHIFT | C26: INFRADIGITAL_N2 | D26: REMOTO / BH | E26: JOSE GERALDO | F26: 31 98773-7542 | G26: =H25 -> 46061.437 | H26: =G26+I26 -> 46061.479 | I26: 0.041666667 | J26: A Iniciar no prazo
A27: 45 | B27: ATIVIDADE DE ROLLBACK - AJUSTAR ALIAS DNS | C27: WINDOWS_N2 | D27: REMOTO / SP | E27: GLADYSTON | F27: 11 98623-8827 | G27: =G26 -> 46061.437 | H27: =G27+I27 -> 46061.479 | I27: 0.041666667 | J27: A Iniciar no prazo
A28: 45 | B28: ATIVIDADE DE ROLLBACK - EXECUTAR VIRADA DE PRODUÇÃO PARA SCN | C28: ORACLE_N2 | D28: REMOTO / SP | E28: PUNTEL | F28: 31 98758-7194 | G28: =G26 -> 46061.437 | H28: =G28+I28 -> 46061.479 | I28: 0.041666667 | J28: A Iniciar no prazo
A29: 45 | B29: ATIVIDADE DE ROLLBACK - DESLIGAR SERVIDORES E RELIGAR NA ORIGEM | C29: UNIX_N2 | D29: REMOTO / BH | E29: FRED CREPALDI | F29: 31 98801-0188 | G29: =G26 -> 46061.437 | H29: =G29+I29 -> 46061.479 | I29: 0.041666667 | J29: A Iniciar no prazo
A30: 48 | B30: ATIVIDADE DE ROLLBACK - SUBIR APLICAÇÃO (ARCOS PRD) DOS MICROSERVIÇOS | C30: INFRADIGITAL_N2 | D30: REMOTO / BH | E30: JOSE GERALDO | F30: 31 98575-1352 | G30: =H28 -> 46061.479 | H30: =G30+I30 -> 46061.604 | I30: 0.125 | J30: A Iniciar no prazo
A31: 50 | B31: ATIVIDADE DE ROLLBACK - VALIDAR APLICAÇÃO | C31: JORNADAL2O_N2 | D31: REMOTO / RJ | E31: JEFFERSON LEITE | F31: 61 986558588 | G31: =H30 -> 46061.604 | H31: =G31+I31 -> 46061.771 | I31: 0.16666667 | J31: A Iniciar no prazo
A32: 50 | B32: ATIVIDADE DE ROLLBACK - VALIDAR APLICAÇÃO | C32: JORNADAFULF_N2 | D32: REMOTO / SP | E32: MICHAEL D SILVA | F32: 19 98349-4052 | G32: =H30 -> 46061.604 | H32: =G32+I32 -> 46061.771 | I32: 0.16666667 | J32: A Iniciar no prazo
A33: 30 | B33: ATIVIDADE DE ROLLBACK -VALIDAR APLICAÇÃO PELA ÁREA USUÁRIA | C33: JORNADAFULF_N2 | E33: ??? | G33: =H30 -> 46061.604 | H33: =G33+I33 -> 46061.771 | I33: 0.16666667 | J33: A Iniciar no prazo
A34: 55 | B34: ATIVIDADE DE ROLLBACK - RETIRAR DE HOLD JOBS E CADEIAS CONTROL-M | C34: PCP_N2 | D34: REMOTO / DF | E34: ROBERTO MAIA | F34: 61 98427-5240 | G34: =H32 -> 46061.771 | H34: =G34+I34 -> 46061.812 | I34: 0.041666667 | J34: A Iniciar no prazo
A35: 55 | B35: ATIVIDADE DE ROLLBACK - LIBERAR POLÍTICAS DE BACKUP E JOBS CONTROL-M | C35: BACKUPPLANEJAMENTO_N2 | D35: REMOTO / DF | E35: RAFAEL SOUSA | F35: 61 98497-4792 | G35: =H33 -> 46061.771 | H35: =G35+I35 -> 46061.812 | I35: 0.041666667 | J35: A Iniciar no prazo
A36: 60 | B36: ENCERRAR CRQ | C36: IMPLANTACAOINFRATI_N2 | D36: REMOTO / BH | E36: RENATO ASSIS | F36: 31 98207-8920 | G36: =H35 -> 46061.812 | H36: =G36+I36 -> 46061.833 | I36: 0.020833333 | J36: A Iniciar no prazo

Sheet CRQ34494 - NFS2
A1: Seq | B1: Atividade | C1: Grupo | D1: localidade | E1: Executor | F1: Telefone | G1: Inicio | H1: Fim | I1: Tempo | J1: Status
A2: 5 | B2: INÍCIO CRQ | C2: IMPLANTACAOINFRATI_N2 | D2: REMOTO / DF | E2: FILIPE LIMA | F2: 61 98628-3620 | G2: 46060.785 | H2: =G2+I2 -> 46060.792 | I2: 0.0069444444 | J2: A Iniciar no prazo
A3: 10 | B3: STOP APLICAÇÃO SMARTCOPPER | C3: IMPLANTACAOINFRATI_N2 | D3: REMOTO / DF | E3: FILIPE LIMA | F3: 61 98628-3620 | G3: 46060.792 | H3: =G3+I3 -> 46060.854 | I3: 0.0625 | J3: A Iniciar no prazo
A4: 11 | B4: DESMONTAR FS NFS NOS SERVIDORES IMPACTADOS | C4: STORAGE_N3 | D4: REMOTO / BH | E4: FREDERICO M CREPALDI | F4: 31 98758-6334 | G4: =H3 -> 46060.854 | H4: =G4+I4 -> 46060.896 | I4: 0.041666667 | J4: A Iniciar no prazo
A5: 14 | B5: SINCRONISMO NFS E DESATIVAÇÃO IP'S SCN | C5: STORAGE_N3 | D5: REMOTO / BH | E5: EMIDIO MACEDO | F5: 31 98758-6334 | G5: =H4 -> 46060.896 | H5: =G5+I5 -> 46060.958 | I5: 0.0625 | J5: A Iniciar no prazo
A6: 13 | B6: AGUARDANDO EXECUÇÃO CRQ DE REDES (CRQ000000034373) | C6: REDES | D6: PRESENCIAL / RJ | E6: FRED POHL | F6: 31 98852-4355 | G6: ='[1]CRQ34373 - REDE2'!G17 -> 46060.958 | H6: =G6+I6 -> 46061.073 | I6: 0.11458333 | J6: N/A
A7: 14 | B7: REMOUNT DO NFS NOS SERVIDORES IMPACTADOS | C7: STORAGE_N3 | D7: REMOTO / BH | E7: EMIDIO MACEDO | F7: 31 98758-6334 | G7: =H6 -> 46061.073 | H7: =G7+I7 -> 46061.115 | I7: 0.041666667 | J7: A Iniciar no prazo
A8: 15 | B8: REMOÇÃO DOS PVCS APONTANDO PARA O ANTIGO NFS (CRQ000000033493) | C8: INFRADIGITAL_N2 | D8: REMOTO / BH | E8: JOSE GERALDO | F8: 31 98773-7542 | G8: =H6 -> 46061.073 | H8: =G8+I8 -> 46061.115 | I8: 0.041666667 | J8: A Iniciar no prazo
A9: 15 | B9: CRIAÇÃO DOS PVCS APONTANDO PARA O NOVO NFS (CRQ000000033493) | C9: INFRADIGITAL_N2 | D9: REMOTO / BH | E9: JOSE GERALDO | F9: 31 98773-7542 | G9: =H6 -> 46061.073 | H9: =G9+I9 -> 46061.115 | I9: 0.041666667 | J9: A Iniciar no prazo
A10: 35 | B10: START APLICAÇÃO SMARTCOPPER | C10: IMPLANTACAOINFRATI_N2 | D10: REMOTO / DF | E10: FILIPE LIMA | F10: 61 98628-3620 | G10: =H7 -> 46061.115 | H10: =G10+I10 -> 46061.156 | I10: 0.041666667 | J10: A Iniciar no prazo
A11: 40 | B11: VALIDAR APLICAÇÃO SMARTCOPPER | C11: IMPLANTACAOINFRATI_N2 | D11: REMOTO / DF | E11: FILIPE LIMA | F11: 61 98628-3620 | G11: =H10 -> 46061.156 | H11: =G11+I11 -> 46061.198 | I11: 0.041666667 | J11: A Iniciar no prazo
A12: ROLLBACK | J12: N/A
A13: 45 | B13: ATIVIDADE DE ROLLBACK - STOP APLICAÇÃO SMARTCOPPER | C13: IMPLANTACAOINFRATI_N2 | D13: REMOTO / DF | E13: FILIPE LIMA | F13: 61 98628-3620 | G13: =H11 -> 46061.198 | H13: =G13+I13 -> 46061.24 | I13: 0.041666667 | J13: A Iniciar no prazo
A14: 50 | B14: ATIVIDADE DE ROLLBACK - DESMONTAR FS NFS NOS SERVIDORES IMPACTADOS | C14: STORAGE_N3 | D14: REMOTO / BH | E14: EMIDIO MACEDO | F14: 31 98758-6334 | G14: =H13 -> 46061.24 | H14: =G14+I14 -> 46061.281 | I14: 0.041666667 | J14: A Iniciar no prazo
A15: 55 | B15: ATIVIDADE DE ROLLBACK - REAPONTAMENTO E REMOUNT DO NFS NOS SERVIDORES IMPACTADOS | C15: STORAGE_N3 | D15: REMOTO / BH | E15: EMIDIO MACEDO | F15: 31 98758-6334 | G15: =H14 -> 46061.281 | H15: =G15+I15 -> 46061.323 | I15: 0.041666667 | J15: A Iniciar no prazo
A16: 60 | B16: ATIVIDADE DE ROLLBACK - REAPONTAMENTO DOS PVCS PARA O ANTIGO NFS | C16: INFRADIGITAL_N2 | D16: REMOTO / BH | E16: JOSE GERALDO | F16: 31 98773-7542 | G16: =H15 -> 46061.323 | H16: =G16+I16 -> 46061.365 | I16: 0.041666667 | J16: A Iniciar no prazo
A17: 65 | B17: ATIVIDADE DE ROLLBACK - START APLICAÇÃO SMARTCOPPER | C17: IMPLANTACAOINFRATI_N2 | D17: REMOTO / DF | E17: FILIPE LIMA | F17: 61 98628-3620 | G17: =H16 -> 46061.365 | H17: =G17+I17 -> 46061.406 | I17: 0.041666667 | J17: A Iniciar no prazo
A18: 70 | B18: ATIVIDADE DE ROLLBACK - VALIDAR APLICAÇÃO SMARTCOPPER | C18: IMPLANTACAOINFRATI_N2 | D18: REMOTO / DF | E18: FILIPE LIMA | F18: 61 98628-3620 | G18: =H17 -> 46061.406 | H18: =G18+I18 -> 46061.448 | I18: 0.041666667 | J18: A Iniciar no prazo
A19: 75 | B19: ENCERRAR CRQ | C19: IMPLANTACAOINFRATI_N2 | D19: REMOTO / DF | E19: FILIPE LIMA | F19: 61 98628-3620 | G19: =H18 -> 46061.448 | H19: =G19+I19 -> 46061.469 | I19: 0.020833333 | J19: A Iniciar no prazo
N39: Rótulos de Linha | O39: Contagem de Atividade
N40: A Iniciar no prazo | O40: 16
N41: N/A
L42: 0.0625 | N42: Total Geral | O42: 16

Sheet CRQ34510 - SI2
A1: Seq | B1: Atividade | C1: Grupo | D1: Localidade | E1: Executor | F1: Telefone | G1: Inicio | H1: Fim | I1: Tempo | J1: Status
A2: 5 | B2: INÍCIO CRQ | C2: IMPLANTACAOINFRATI_N2 | D2: REMOTO / BH | E2: RENATO VIEIRA | F2: 31 97501-9451 | G2: 46060.535 | H2: =G2+I2 -> 46060.542 | I2: 0.0069444444 | J2: Concluído
A3: 10 | B3: BACKUP FULL DOS ICS DA APP IDENTIDADE E COFRE DE CONTATO (EDIR) | C3: BACKUP_N1 | D3: REMOTO / DF | E3: ALEX B SOARES | F3: 61 98596-4456 | G3: =H2 -> 46060.542 | H3: =G3+I3 -> 46060.75 | I3: 0.20833333 | J3: Concluído | L3: Rótulos de Linha | M3: Contagem de Atividade
A4: 15 | B4: STOP DOS JOBS E CADEIAS CONTROL-M | C4: PCP_N2 | D4: REMOTO / DF | E4: SILAS DE OLIVEIRA | F4: 61 9844-91418 | G4: =H3 -> 46060.75 | H4: =G4+I4 -> 46060.792 | I4: 0.041666667 | J4: Concluído | L4: A Iniciar no prazo | M4: 25
A5: 15 | B5: STOP DAS ROTINAS DE BACKUP E JOBS CONTROL-M | C5: BACKUPIMPLANTACAO_N2 | D5: REMOTO / DF | E5: ALEX B SOARES | F5: 61 98596-4456 | G5: =H3 -> 46060.75 | H5: =G5+I5 -> 46060.792 | I5: 0.041666667 | J5: Concluído | K5: parar vms do Identidade | L5: Total Geral | M5: 25
A6: 20 | B6: PARAR APLICAÇÕES Identidade e cofre de contato | C6: IDDIGITAL_N2 | D6: REMOTO / DF | E6: ALAN BREGUES | F6: 31 98517-9909 | G6: =H5 -> 46060.792 | H6: =G6+I6 -> 46060.833 | I6: 0.041666667 | J6: A Iniciar no prazo
A7: 25 | B7: AJUSTAR ALIAS DNS PARA OS NOVOS SERVIDORES | C7: WINDOWS_N2 | D7: REMOTO / BH | E7: GLADYSTON | F7: 31 98877-9940 | G7: =H6 -> 46060.833 | H7: =G7+I7 -> 46060.875 | I7: 0.041666667 | J7: A Iniciar no prazo
A8: 25 | B8: EXECUTAR VIRADA DE PRODUÇÃO PARA ARCOS | C8: ORACLE_N2 | D8: REMOTO / BH | E8: CHRISTIAN | F8: (31) 98872-9857 | G8: =H6 -> 46060.833 | H8: =G8+I8 -> 46060.875 | I8: 0.041666667 | J8: A Iniciar no prazo
A9: 25 | B9: DESLIGAR ICS RELACIONADOS | C9: UNIX_N2 | D9: REMOTO / BH | E9: FREDERICO M CREPALDI | F9: 31 98758-6334 | G9: =H6 -> 46060.833 | H9: =G9+I9 -> 46060.875 | I9: 0.041666667 | J9: A Iniciar no prazo
A10: 25 | B10: MIGRAÇÃO DOS ICS RELACIONADOS | C10: UNIX_N2 | D10: REMOTO / BH | E10: FREDERICO M CREPALDI | F10: 31 98758-6334 | G10: =H6 -> 46060.833 | H10: =G10+I10 -> 46060.875 | I10: 0.041666667 | J10: A Iniciar no prazo
A11: 25 | B11: MONITORAR GUARDICORE NOS SERVIDORES | C11: SEGSDI_N2 | D11: REMOTO / SP | E11: TIAGO FERREIRA CAMPOS | F11: 11 98268-7112 | G11: =H6 -> 46060.833 | H11: =G11+I11 -> 46060.875 | I11: 0.041666667 | J11: A Iniciar no prazo
A12: 28 | B12: SUBIR APLICAÇÃO Identidade e cofre de contato | C12: IDDIGITAL_N2 | D12: REMOTO / DF | E12: ALAN BREGUES | F12: 31 98517-9909 | G12: =H10 -> 46060.875 | H12: =G12+I12 -> 46060.917 | I12: 0.041666667 | J12: A Iniciar no prazo
A13: 30 | B13: AJUSTAR DNS NDS | C13: WINDOWS_N2 | D13: REMOTO / BH | E13: GLADYSTON | F13: 31 98877-9940 | G13: =H12 -> 46060.917 | H13: =G13+I13 -> 46060.958 | I13: 0.041666667 | J13: A Iniciar no prazo
A14: 30 | B14: VALIDAR APLICAÇÃO | C14: IDDIGITAL_N2 | D14: REMOTO / DF | E14: ALAN BREGUES | F14: 31 98517-9909 | G14: =H12 -> 46060.917 | H14: =G14+I14 -> 46060.958 | I14: 0.041666667 | J14: A Iniciar no prazo
A15: 33 | B15: VIRADA DA REDE | G15: ='[1]CRQ34373 - REDE2'!G17 -> 46060.958 | H15: ='[1]CRQ34373 - REDE2'!H17 -> 46061.073 | J15: N/A
A16: 35 | B16: LIBERAR ROTINAS DE BACKUP E JOBS CONTROL-M | C16: BACKUPIMPLANTACAO_N2 | D16: REMOTO / DF | E16: RAFAEL SOUSA | F16: 61 98497-4792 | G16: ='[1]CRQ34373 - REDE2'!H17 -> 46061.073 | H16: =G16+I16 -> 46061.115 | I16: 0.041666667 | J16: A Iniciar no prazo
A17: 35 | B17: RETIRAR DE HOLD JOBS E CADEIAS CONTROL-M | C17: PCP_N2 | D17: REMOTO / DF | E17: ROBERTO MAIA | F17: 61 98427-5240 | G17: ='[1]CRQ34373 - REDE2'!H17 -> 46061.073 | H17: =G17+I17 -> 46061.115 | I17: 0.041666667 | J17: A Iniciar no prazo
A18: ROLLBACK | J18: N/A
A19: 38 | B19: ATIVIDADE DE ROLLBACK - PARAR APLICAÇÃO Identidade e cofre de contato | C19: IDDIGITAL_N2 | D19: REMOTO / DF | E19: ALAN BREGUES | F19: 31 98517-9909 | G19: ='[1]CRQ34373 - REDE2'!H25 -> 46061.115 | H19: =G19+I19 -> 46061.156 | I19: 0.041666667 | J19: A Iniciar no prazo
A20: 45 | B20: ATIVIDADE DE ROLLBACK - AJUSTAR ALIAS DNS | C20: WINDOWS_N2 | D20: REMOTO / BH | E20: GLADYSTON | F20: 31 98877-9940 | G20: =H19 -> 46061.156 | H20: =G20+I20 -> 46061.198 | I20: 0.041666667 | J20: A Iniciar no prazo
B21: ATIVIDADE DE ROLLBACK - EXECUTAR VIRADA DE PRODUÇÃO PARA SCN | C21: ORACLE_N2 | D21: REMOTO / BH | E21: LUIZ PUNTEL | F21: 31 98758-7194 | G21: =G20 -> 46061.156 | H21: =G21+I21 -> 46061.198 | I21: 0.041666667 | J21: A Iniciar no prazo
A22: 45 | B22: ATIVIDADE DE ROLLBACK - DESLIGAR SERVIDORES E RELIGAR NA ORIGEM | C22: UNIX_N2 | D22: REMOTO / BH | E22: FREDERICO M CREPALDI | F22: 31 98758-6334 | G22: =G20 -> 46061.156 | H22: =G22+I22 -> 46061.198 | I22: 0.041666667 | J22: A Iniciar no prazo
A23: 45 | B23: ATIVIDADE DE ROLLBACK - EXECUTAR VIRADA DE PRODUÇÃO PARA SCN | C23: UNIX_N2 | D23: REMOTO / BH | E23: FREDERICO M CREPALDI | F23: 31 98758-6334 | G23: =G20 -> 46061.156 | H23: =G23+I23 -> 46061.198 | I23: 0.041666667 | J23: A Iniciar no prazo
A24: 48 | B24: ATIVIDADE DE ROLLBACK - START DA APLICAÇÃO | C24: IDDIGITAL_N2 | D24: REMOTO / DF | E24: ALAN BREGUES | F24: 31 98517-9909 | G24: =H23 -> 46061.198 | H24: =G24+I24 -> 46061.24 | I24: 0.041666667 | J24: A Iniciar no prazo
A25: 30 | B25: AJUSTAR DNS NDS | C25: WINDOWS_N2 | D25: REMOTO / BH | E25: GLADYSTON | F25: 31 98877-9940 | G25: =H24 -> 46061.24 | H25: =G25+I25 -> 46061.281 | I25: 0.041666667 | J25: A Iniciar no prazo
A26: 30 | B26: ATIVIDADE DE ROLLBACK -VALIDAR APLICAÇÃO | C26: IDDIGITAL_N2 | D26: REMOTO / DF | E26: ALAN BREGUES | F26: 31 98517-9909 | G26: =H24 -> 46061.24 | H26: =G26+I26 -> 46061.323 | I26: 0.083333333 | J26: A Iniciar no prazo
A27: 55 | B27: ATIVIDADE DE ROLLBACK - RETIRAR DE HOLD JOBS E CADEIAS CONTROL-M | C27: PCP_N2 | D27: REMOTO / DF | E27: ROBERTO MAIA | F27: 61 98427-5240 | G27: =H26 -> 46061.323 | H27: =G27+I27 -> 46061.365 | I27: 0.041666667 | J27: A Iniciar no prazo
A28: 55 | B28: ATIVIDADE DE ROLLBACK - LIBERAR POLÍTICAS DE BACKUP E JOBS CONTROL-M | C28: BACKUPIMPLANTACAO_N2 | D28: REMOTO / DF | E28: RAFAEL SOUSA | F28: 61 98497-4792 | G28: =H26 -> 46061.323 | H28: =G28+I28 -> 46061.365 | I28: 0.041666667 | J28: A Iniciar no prazo
A29: 60 | B29: ENCERRAR CRQ | C29: IMPLANTACAOINFRATI_N2 | D29: REMOTO / BH | E29: RENATO VIEIRA | F29: 31 97501-9451 | G29: =H28 -> 46061.365 | H29: =G29+I29 -> 46061.385 | I29: 0.020833333 | J29: A Iniciar no prazo
B33: CARKPW01A | C33: COFRE DE SENHAS - PRD
B34: CARKPW02 | C34: COFRE DE SENHAS - PRD
B35: CARKPW03 | C35: COFRE DE SENHAS - PRD
B36: CARKPX01 | C36: COFRE DE SENHAS - PRD
B37: CARKPX02 | C37: COFRE DE SENHAS - PRD
B38: CARKPX03 | C38: COFRE DE SENHAS - PRD
B39: CARKPX04A | C39: COFRE DE SENHAS - PRD
B40: CARKPX04B | C40: COFRE DE SENHAS - PRD

Sheet Visao executiva CRQs 31jan

Sheet CRQ34373 - REDE
A1: Seq | B1: Atividade | C1: Grupo | D1: Localidade | E1: Executor | F1: Telefone | G1: Inicio | H1: Fim | I1: Tempo | J1: Status
A2: 5 | B2: INÍCIO CRQ | C2: IMPLANTACAOINFRATI_N2 | D2: REMOTO / BH | E2: RENATO D VIEIRA | F2: 31 98207-8920 | G2: 46053.535 | H2: =G2+I2 -> 46053.542 | I2: 0.0069444444 | J2: Concluído
A3: 10 | B3: VALIDAÇÃO BACKUP DOS ICS RELACIONADOS | C3: BACKUPPLANEJAMENTO_N2 | D3: REMOTO / DF | E3: RAFAEL SOUSA | F3: 61 98497-4792 | G3: =H2 -> 46053.542 | H3: =G3+I3 -> 46053.708 | I3: 0.16666667 | J3: Concluído | L3: Rótulos de Linha | M3: Contagem de Atividade
A4: 15 | B4: STOP DOS JOBS E CADEIAS CONTROL-M PRODUÇÃO | C4: PCP_N2 | D4: REMOTO / DF | E4: SILAS DE OLIVEIRA | F4: 61 9844-91418 | G4: =H3 -> 46053.708 | H4: =G4+I4 -> 46053.75 | I4: 0.041666667 | J4: Concluído | L4: A Iniciar fora do prazo | M4: 26
A5: 15 | B5: STOP DOS JOBS E CADEIAS CONTROL-M BACKUP | C5: BACKUPPLANEJAMENTO_N2 | D5: REMOTO / DF | E5: RAFAEL SOUSA | F5: 61 98497-4792 | G5: =H3 -> 46053.708 | H5: =G5+I5 -> 46053.75 | I5: 0.041666667 | J5: Concluído | L5: A Iniciar no prazo | M5: 33
A6: 18 | B6: REALIZAR BACKUP DOS ELEMENTOS DE REDE | C6: REDES | D6: PRESENCIAL / RJ | E6: FRED POLH | F6: 31 98852-4355 | G6: =H5 -> 46053.75 | H6: =G6+I6 -> 46053.792 | I6: 0.041666667 | J6: Concluído | L6: Concluído | M6: 11
A7: 18 | B7: STOP DA APLICAÇÃO SOM/OMR | C7: SOM_N2 | D7: REMOTO / DF | E7: DIONEY YANO | F7: 61 98466-4590 | G7: =H6 -> 46053.792 | H7: =G7+I7 -> 46053.833 | I7: 0.041666667 | J7: Concluído | L7: Em execução fora do prazo | M7: 1
A8: 19 | B8: STOP DA APLICAÇÃO SIS ATIVAÇÃO/NETQ | C8: SISATIVACAOFIXA_N2 | D8: REMOTO / DF | E8: ARSENIO SANTOS | F8: 61 98665-4644 | G8: =H6 -> 46053.792 | H8: =G8+I8 -> 46053.833 | I8: 0.041666667 | J8: Concluído | L8: N/A | M8: 3
A9: 19 | B9: STOP DA APLICAÇÃO SOA | C9: INTEGRACAO_N2 | D9: REMOTO / DF | E9: LEANDRO CONTE | F9: 61 98595-4649 | G9: =H6 -> 46053.792 | H9: =G9+I9 -> 46053.833 | I9: 0.041666667 | J9: Concluído | L9: Total Geral | M9: 74
A10: 19 | B10: STOP DA APLICAÇÃO NETWIN | C10: NETWIN_N2 | D10: REMOTO / DF | E10: DANIEL PRAXEDES | F10: 61 98491-6039 | G10: =H6 -> 46053.792 | H10: =G10+I10 -> 46053.833 | I10: 0.041666667 | J10: Concluído
A11: 19 | B11: STOP DA APLICAÇÃO GCP | C11: JORNADAL2O_N2 | D11: REMOTO / RJ | E11: ALEX OREM | F11: 21 98528- 5400 | G11: =H6 -> 46053.792 | H11: =G11+I11 -> 46053.833 | I11: 0.041666667 | J11: Concluído
A12: 20 | B12: STOP DO BDs e GRID que NÃO serão migrados das aplicações acima | C12: ORACLE_N2 | D12: REMOTO /BH | E12: LUIZ PUNTEL | F12: 31 98758-7194 | G12: =H11 -> 46053.833 | H12: =G12+I12 -> 46053.917 | I12: 0.083333333 | J12: Concluído
A13: 19 | B13: CRQ SI | D13: REMOTO / DF | E13: ROMANO GOMES | F13: 61 98574-9927 | G13: ='CRQ33459 - SI'!G7 -> 46053.792 | H13: ='CRQ33459 - SI'!H14 -> 46053.958 | J13: N/A
A14: 19 | B14: CRQ Openshift | D14: REMOTO / BH | E14: RENATO D VIEIRA | F14: 31 98207-8920 | G14: ='CRQ033493 - OPENSHIFT'!G6 -> 46053.792 | H14: ='CRQ033493 - OPENSHIFT'!H14 -> 46053.958 | J14: N/A
A15: 19 | B15: CRQ NAS | D15: REMOTO / DF | E15: FILIPE LIMA | F15: 61 98628-3620 | G15: ='CRQ34463 - NFS'!G2 -> 46053.785 | H15: ='CRQ34463 - NFS'!H7 -> 46053.958 | J15: N/A
A16: bo | B16: REALIZAR MIGRAÇÃO DA VLANS PARA O DC ARCOS | C16: REDES | D16: PRESENCIAL / RJ | E16: FRED POLH | F16: 31 98852-4355 | G16: =H13 -> 46053.958 | H16: =G16+I16 -> 46054.073 | I16: 0.11458333 | J16: Não executada - Rollback
A17: 27 | B17: START DOS BDs .....(add as outras aplicações) | C17: ORACLE_N2 | D17: REMOTO / BH | E17: LUIZ PUNTEL | F17: 31 98758-7194 | G17: =H16 -> 46054.073 | H17: =G17+I17 -> 46054.115 | I17: 0.041666667 | J17: Não executada - Rollback
A18: 27 | B18: Validar TODAS as outras aplicações | C18: JORNADAFULF_N2 | D18: REMOTO / DF | E18: DIEGO ARCANJO | F18: 61 98679-4930 | G18: =H16 -> 46054.073 | H18: =G18+I18 -> 46054.115 | I18: 0.041666667 | J18: Não executada - Rollback
A19: 27 | B19: Validar TODAS as outras aplicações | C19: JORNADAL2O_N2 | D19: REMOTO / DF | E19: MARCIO ROBERTO | F19: 61 98409-4671 | G19: =H16 -> 46054.073 | H19: =G19+I19 -> 46054.115 | I19: 0.041666667 | J19: Não executada - Rollback
A20: 27 | B20: Validar TODAS aplicações (Ewerson) | C20: JORNADACORP_N2 | D20: REMOTO / RJ | E20: ROBERTO REBEQUE | F20: 21 98834-3136 | G20: =H16 -> 46054.073 | H20: =G20+I20 -> 46054.115 | I20: 0.041666667 | J20: Não executada - Rollback
A21: 27 | B21: Validar ITSM | C21: ITSM_N2 | D21: REMOTO / DF | E21: TASSIO COSTA | F21: 61 98618-0128 | G21: =H16 -> 46054.073 | H21: =G21+I21 -> 46054.115 | I21: 0.041666667 | J21: Não executada - Rollback
A22: 27 | B22: Validar Monitoração | C22: MONITORACAO_N2 | D22: REMOTO / TO | E22: JOSE FRANCISCO KLAUS | F22: 48 99988-0876 | G22: =H16 -> 46054.073 | H22: =G22+I22 -> 46054.115 | I22: 0.041666667 | J22: Não executada - Rollback
A23: 27 | B23: Validar CMDB | C23: CMDB_N2 | D23: REMOTO / PR | E23: RAFAEL DEMBICKI | F23: 41 99145- 3635 | G23: =H16 -> 46054.073 | H23: =G23+I23 -> 46054.115 | I23: 0.041666667 | J23: Não executada - Rollback
A24: 27 | B24: Validar aplicações SI | C24: IDDIGITAL_N2 | D24: REMOTO / DF | E24: ROMANO GOMES | F24: 61 985749927 | G24: =H16 -> 46054.073 | H24: =G24+I24 -> 46054.115 | I24: 0.041666667 | J24: Não executada - Rollback
A25: 27 | B25: Validar aplicações SI (COPS) | C25: SOC_N2 | D25: REMOTO / RJ | E25: MARCELO MONTEZUMA | F25: 21 98864-0464 | G25: =H16 -> 46054.073 | H25: =G25+I25 -> 46054.115 | I25: 0.041666667 | J25: Não executada - Rollback
A26: 28 | B26: START DA APLICAÇÃO SIS ATIVAÇÃO/ NETQ | C26: SISATIVACAOFIXA_N2 | D26: REMOTO / DF | E26: ARSENIO SANTOS | F26: 61 98665-4644 | G26: =H17 -> 46054.115 | H26: =G26+I26 -> 46054.156 | I26: 0.041666667 | J26: Não executada - Rollback
A27: 28 | B27: START DA APLICAÇÃO SOA | C27: INTEGRACAO_N2 | D27: REMOTO / DF | E27: LEANDRO CONTE | F27: 61 98595-4649 | G27: =H17 -> 46054.115 | H27: =G27+I27 -> 46054.156 | I27: 0.041666667 | J27: Não executada - Rollback
A28: 28 | B28: START DA APLICAÇÃO NETWIN | C28: NETWIN_N2 | D28: REMOTO / DF | E28: DANIEL PRAXEDES | F28: 61 98491-6039 | G28: =H17 -> 46054.115 | H28: =G28+I28 -> 46054.156 | I28: 0.041666667 | J28: Não executada - Rollback
A29: 28 | B29: START DA APLICAÇÃO GCP | C29: JORNADAL2O_N2 | D29: REMOTO / RJ | E29: ALEX OREM | F29: 21 98528- 5400 | G29: =H17 -> 46054.115 | H29: =G29+I29 -> 46054.156 | I29: 0.041666667 | J29: Não executada - Rollback
A30: 28 | B30: Validar TODAS as outras aplicações | C30: JORNADAFULF_N2 | D30: REMOTO / DF | E30: DIEGO ARCANJO | F30: 61 98679-4930 | G30: =H25 -> 46054.115 | H30: =G30+I30 -> 46054.156 | I30: 0.041666667 | J30: Não executada - Rollback
A31: 28 | B31: Validar TODAS as outras aplicações | C31: JORNADAL2O_N2 | D31: REMOTO / DF | E31: MARCIO ROBERTO | F31: 61 98409-4671 | G31: =H25 -> 46054.115 | H31: =G31+I31 -> 46054.156 | I31: 0.041666667 | J31: Não executada - Rollback
A32: 28 | B32: Validar Monitoração | C32: MONITORACAO_N2 | D32: REMOTO / TO | E32: JOSE FRANCISCO KLAUS | F32: 48 99988-0876 | G32: =H25 -> 46054.115 | H32: =G32+I32 -> 46054.156 | I32: 0.041666667 | J32: Não executada - Rollback
A33: 28 | B33: Validar CMDB | C33: CMDB_N2 | D33: REMOTO / PR | E33: RAFAEL DEMBICKI | F33: 41 99145- 3635 | G33: =H25 -> 46054.115 | H33: =G33+I33 -> 46054.156 | I33: 0.041666667 | J33: Não executada - Rollback
A34: 28 | B34: Validar aplicações SI | C34: IDDIGITAL_N2 | D34: REMOTO / DF | E34: ROMANO GOMES | F34: 61 985749927 | G34: =H25 -> 46054.115 | H34: =G34+I34 -> 46054.156 | I34: 0.041666667 | J34: Não executada - Rollback
A35: 29 | B35: START DA APLICAÇÃO SOM/OMR | C35: SOM_N2 | D35: REMOTO / DF | E35: DIONEY YANO | F35: 61 98466-4590 | G35: =H28 -> 46054.156 | H35: =G35+I35 -> 46054.198 | I35: 0.041666667 | J35: Não executada - Rollback
A36: 30 | B36: VALIDAR APLICAÇÃO SIS ATIVAÇÃO/NETQ | C36: SISATIVACAOFIXA_N2 | D36: REMOTO / DF | E36: ARSENIO SANTOS | F36: 61 98665-4644 | G36: =H35 -> 46054.198 | H36: =G36+I36 -> 46054.281 | I36: 0.083333333 | J36: Não executada - Rollback
A37: 30 | B37: VALIDAR SOA | C37: INTEGRACAO_N2 | D37: REMOTO / DF | E37: LEANDRO CONTE | F37: 61 98595-4649 | G37: =H35 -> 46054.198 | H37: =G37+I37 -> 46054.281 | I37: 0.083333333 | J37: Não executada - Rollback
A38: 30 | B38: VALIDAR NETWIN | C38: NETWIN_N2 | D38: REMOTO / DF | E38: DANIEL PRAXEDES | F38: 61 98491-6039 | G38: =H35 -> 46054.198 | H38: =G38+I38 -> 46054.281 | I38: 0.083333333 | J38: Não executada - Rollback
A39: 30 | B39: VALIDAR SOM/OMR | C39: SOM_N2 | D39: REMOTO / DF | E39: DIONEY YANO | F39: 61 98466-4590 | G39: =H35 -> 46054.198 | H39: =G39+I39 -> 46054.281 | I39: 0.083333333 | J39: Não executada - Rollback
A40: 30 | B40: VALIDAR GCP | C40: JORNADAL2O_N2 | D40: REMOTO / RJ | E40: ALEX OREM | F40: 21 98528- 5400 | G40: =H35 -> 46054.198 | H40: =G40+I40 -> 46054.281 | I40: 0.083333333 | J40: Não executada - Rollback
...

Sheet Validação dos dados
A1: A Iniciar no prazo
A2: A Iniciar fora do prazo
A3: Em execução no prazo
A4: Em execução fora do prazo
A5: Concluído
A6: N/A
A7: Não executada - Rollback

Sheet CRQ033493 - OPENSHIFT
A1: Seq | B1: Atividade | C1: Grupo | D1: localidade | E1: Executor | F1: Telefone | G1: Inicio | H1: Fim | I1: Tempo | J1: Status | L1: PORTAL OPERACIONAL - PCW - PRD
A2: 5 | B2: INÍCIO CRQ | C2: IMPLANTACAOINFRATI_N2 | D2: REMOTO / BH | E2: RENATO VIEIRA | F2: 31 97501-9451 | G2: 46053.701 | H2: =G2+I2 -> 46053.708 | I2: 0.0069444444 | J2: Concluído | L2: [VTAL] GEOSITE - PRD
A3: 10 | B3: BACKUP FULL DOS ICS RELACIONADOS | C3: BACKUPPLANEJAMENTO_N2 | D3: REMOTO / DF | E3: ALEX B SOARES | F3: 61 98596-4456 | G3: =H2 -> 46053.708 | H3: =G3+I3 -> 46053.75 | I3: 0.041666667 | J3: Concluído | L3: GEOSITE LOGRADOURO - PRD | N3: Rótulos de Linha | O3: Total
A4: 15 | B4: STOP DOS JOBS E CADEIAS CONTROL-M | C4: PCP_N2 | D4: REMOTO / DF | E4: SILAS DE OLIVEIRA | F4: 61 9844-91418 | G4: =H3 -> 46053.75 | H4: =G4+I4 -> 46053.792 | I4: 0.041666667 | J4: Concluído | L4: MICROSSERVICOS CW - PRD | N4: A Iniciar no prazo | O4: 14
A5: 15 | B5: STOP DAS ROTINAS DE BACKUP E JOBS CONTROL-M | C5: BACKUPPLANEJAMENTO_N2 | D5: REMOTO / DF | E5: ALEX B SOARES | F5: 61 98596-4456 | G5: =H3 -> 46053.75 | H5: =G5+I5 -> 46053.792 | I5: 0.041666667 | J5: Concluído | L5: MS ORDER ENTRY - PRD | N5: Concluído | O5: 13
A6: 18 | B6: PARAR APLICAÇÕES (ARCOS E SCN PRD) | C6: INFRADIGITAL_N2 | D6: REMOTO / BH | E6: JOSE GERALDO | F6: 31 98773-7542 | G6: 46053.792 | H6: =G6+I6 -> 46053.854 | I6: 0.0625 | J6: Concluído | L6: MS-COBRANÇA - PRD + MSCGNAT (Openshift) | N6: N/A | O6: 2
A7: 20 | B7: CONFIGURAÇÕES DO DNS/ROTAS OPENSHIFT | C7: INFRADIGITAL_N2 | D7: REMOTO / BH | E7: JOSE GERALDO | F7: 31 98773-7542 | G7: =H6 -> 46053.854 | H7: =G7+I7 -> 46053.917 | I7: 0.0625 | J7: Concluído | L7: ms-fuzzy-availability-check - PRD | N7: A Iniciar fora do prazo | O7: 4
A8: 20 | B8: AJUSTAR ALIAS DNS PARA OS NOVOS SERVIDORES | C8: WINDOWS_N2 | D8: REMOTO / BH | E8: GLADYSTON | F8: 31 98877-9940 | G8: =H6 -> 46053.854 | H8: =G8+I8 -> 46053.917 | I8: 0.0625 | J8: Concluído | N8: Total Geral | O8: 33
A9: 20 | B9: EXECUTAR VIRADA DE PRODUÇÃO PARA ARCOS | C9: ORACLE_N2 | D9: REMOTO / BH | E9: LUIZ PUNTEL | F9: 31 98758-7194 | G9: =H6 -> 46053.854 | H9: =G9+I9 -> 46053.917 | I9: 0.0625 | J9: Concluído | L9: Incluir os nomes dos BDs a serem migrados
A10: 20 | B10: MIGRAÇÃO DOS ICS RELACIONADOS | C10: UNIX_N2 | D10: REMOTO / BH | E10: FREDERICO M CREPALDI | F10: 31 98758-6334 | G10: =H6 -> 46053.854 | H10: =G10+I10 -> 46053.917 | I10: 0.0625 | J10: Concluído
A11: 20 | B11: MONITORAR GUARDICORE NOS SERVIDORES | C11: SEGSDI_N2 | D11: REMOTO / SP | E11: TIAGO FERREIRA CAMPOS | F11: 11 98268-7112 | G11: =H6 -> 46053.854 | H11: =G11+I11 -> 46053.917 | I11: 0.0625 | J11: Concluído
A12: 25 | B12: STOP dos BDs | C12: ORACLE_N2 | D12: REMOTO / BH | E12: LUIZ PUNTEL | F12: 31 98758-7194 | G12: =H8 -> 46053.917 | H12: =G12+I12 -> 46053.979 | I12: 0.0625 | J12: Concluído | L12: Incluir os nomes dos BDs a serem migrados
A13: 26 | B13: REMOÇÃO DOS PVCS APONTANDO PARA O ANTIGO NFS | C13: INFRADIGITAL_N2 | D13: REMOTO / BH | E13: JOSE GERALDO | F13: 31 98773-7542 | G13: =H10 -> 46053.917 | H13: =G13+I13 -> 46053.958 | I13: 0.041666667 | J13: Concluído
A14: 26 | B14: CRIAÇÃO DOS PVCS APONTANDO PARA O NOVO NFS | C14: INFRADIGITAL_N2 | D14: REMOTO / BH | E14: JOSE GERALDO | F14: 31 98773-7542 | G14: =H10 -> 46053.917 | H14: =G14+I14 -> 46053.958 | I14: 0.041666667 | J14: Concluído
B15: CRQ NFS | D15: REMOTO / DF | E15: FILIPE LIMA | F15: 61 98628-3620 | G15: =H6 -> 46053.854 | H15: =G15+I15 -> 46053.979 | I15: 0.125 | J15: N/A
B16: VIRADA da REDE | D16: PRESENCIAL / RJ | E16: FRED POLH | F16: 31 98852-4355 | G16: ='CRQ34373 - REDE'!G16 -> 46053.958 | H16: ='CRQ34373 - REDE'!H16 -> 46054.073 | J16: N/A
A17: 28 | B17: SUBIR APLICAÇÃO (ARCOS PRD) DOS MICROSERVIÇOS | C17: INFRADIGITAL_N2 | D17: REMOTO / BH | E17: JOSE GERALDO | F17: 31 98773-7542 | G17: =H16 -> 46054.073 | H17: =G17+I17 -> 46054.167 | I17: 0.09375 | J17: Não executada - Rollback
A18: 30 | B18: VALIDAR APLICAÇÃO | C18: JORNADAL2O_N2 | D18: REMOTO / RJ | E18: ALEXANDRE ARCOVERDE | F18: 21 98606-3088 | G18: =H17 -> 46054.167 | H18: =G18+I18 -> 46054.333 | I18: 0.16666667 | J18: Não executada - Rollback
A19: 30 | B19: VALIDAR APLICAÇÃO | C19: JORNADAFULF_N2 | D19: REMOTO / SP | E19: MICHAEL D SILVA | F19: 19 98349-4052 | G19: =H17 -> 46054.167 | H19: =G19+I19 -> 46054.333 | I19: 0.16666667 | J19: Não executada - Rollback
A20: 30 | B20: VALIDAR APLICAÇÃO PELA ÁREA USUÁRIA | E20: ??? | G20: =H17 -> 46054.167 | H20: =G20+I20 -> 46054.333 | I20: 0.16666667 | J20: Não executada - Rollback
A21: 35 | B21: LIBERAR ROTINAS DE BACKUP E JOBS CONTROL-M | C21: BACKUPPLANEJAMENTO_N2 | D21: REMOTO / DF | E21: RAFAEL SOUSA | F21: 61 98497-4792 | G21: =H20 -> 46054.333 | H21: =G21+I21 -> 46054.375 | I21: 0.041666667 | J21: Não executada - Rollback
A22: 35 | B22: RETIRAR DE HOLD JOBS E CADEIAS CONTROL-M | C22: PCP_N2 | D22: REMOTO / DF | E22: ROBERTO MAIA | F22: 61 98427-5240 | G22: =H20 -> 46054.333 | H22: =G22+I22 -> 46054.375 | I22: 0.041666667 | J22: Não executada - Rollback
A23: ROLLBACK | J23: N/A
A24: 38 | B24: ATIVIDADE DE ROLLBACK - PARAR APLICAÇÃO | C24: INFRADIGITAL_N2 | D24: REMOTO / BH | E24: THIAGO ROCHAEL | F24: 31 98575-1352 | G24: =H22 -> 46054.375 | H24: =G24+I24 -> 46054.417 | I24: 0.041666667 | J24: Não executada - Rollback
A25: 45 | B25: CONFIGURAÇÕES DO DNS/ROTAS OPENSHIFT | C25: INFRADIGITAL_N2 | D25: REMOTO / BH | E25: THIAGO ROCHAEL | F25: 31 98575-1352 | G25: ='CRQ34373 - REDE'!H53 -> 46054.354 | H25: =G25+I25 -> 46054.396 | I25: 0.041666667 | J25: Concluído
A26: 45 | B26: ATIVIDADE DE ROLLBACK - AJUSTAR ALIAS DNS | C26: WINDOWS_N2 | D26: REMOTO / SP | E26: GLADYSTON | F26: 11 98623-8827 | G26: =G25 -> 46054.354 | H26: =G26+I26 -> 46054.396 | I26: 0.041666667 | J26: Concluído
A27: 45 | B27: ATIVIDADE DE ROLLBACK - EXECUTAR VIRADA DE PRODUÇÃO PARA SCN | C27: ORACLE_N2 | D27: REMOTO / SP | E27: Ed Flavio Confessor | F27: 11 98747-0919 | G27: =G25 -> 46054.354 | H27: =G27+I27 -> 46054.396 | I27: 0.041666667 | J27: Concluído
A28: 45 | B28: ATIVIDADE DE ROLLBACK - DESLIGAR SERVIDORES E RELIGAR NA ORIGEM | C28: UNIX_N2 | D28: REMOTO / BH | E28: FRED CREPALDI | F28: 31 98801-0188 | G28: =G25 -> 46054.354 | H28: =G28+I28 -> 46054.396 | I28: 0.041666667 | J28: Concluído
A29: 48 | B29: ATIVIDADE DE ROLLBACK - SUBIR APLICAÇÃO (ARCOS PRD) DOS MICROSERVIÇOS | C29: INFRADIGITAL_N2 | D29: REMOTO / BH | E29: THIAGO ROCHAEL | F29: 31 98575-1352 | G29: =H27 -> 46054.396 | H29: =G29+I29 -> 46054.521 | I29: 0.125 | J29: Concluído
A30: 50 | B30: ATIVIDADE DE ROLLBACK - VALIDAR APLICAÇÃO | C30: JORNADAL2O_N2 | D30: REMOTO / RJ | E30: ALEXANDRE ARCOVERDE | F30: 21 98606-3088 | G30: =H29 -> 46054.521 | H30: =G30+I30 -> 46054.687 | I30: 0.16666667 | J30: Concluído
A31: 50 | B31: ATIVIDADE DE ROLLBACK - VALIDAR APLICAÇÃO | C31: JORNADAFULF_N2 | D31: REMOTO / SP | E31: MICHAEL D SILVA | F31: 19 98349-4052 | G31: =H29 -> 46054.521 | H31: =G31+I31 -> 46054.687 | I31: 0.16666667 | J31: Concluído
A32: 30 | B32: ATIVIDADE DE ROLLBACK -VALIDAR APLICAÇÃO PELA ÁREA USUÁRIA | C32: JORNADAFULF_N2 | E32: DIEGO A SILVA | G32: =H29 -> 46054.521 | H32: =G32+I32 -> 46054.687 | I32: 0.16666667 | J32: Concluído
A33: 55 | B33: ATIVIDADE DE ROLLBACK - RETIRAR DE HOLD JOBS E CADEIAS CONTROL-M | C33: PCP_N2 | D33: REMOTO / DF | E33: ROBERTO MAIA | F33: 61 98427-5240 | G33: =H31 -> 46054.687 | H33: =G33+I33 -> 46054.729 | I33: 0.041666667 | J33: Concluído
A34: 55 | B34: ATIVIDADE DE ROLLBACK - LIBERAR POLÍTICAS DE BACKUP E JOBS CONTROL-M | C34: BACKUPPLANEJAMENTO_N2 | D34: REMOTO / DF | E34: RAFAEL SOUSA | F34: 61 98497-4792 | G34: =H32 -> 46054.687 | H34: =G34+I34 -> 46054.729 | I34: 0.041666667 | J34: Concluído
A35: 60 | B35: ENCERRAR CRQ | C35: IMPLANTACAOINFRATI_N2 | D35: REMOTO / BH | E35: RENATO D VIEIRA | F35: 31 98207-8920 | G35: =H34 -> 46054.729 | H35: =G35+I35 -> 46054.75 | I35: 0.020833333 | J35: Concluído

Sheet CRQ34463 - NFS
A1: Seq | B1: Atividade | C1: Grupo | D1: localidade | E1: Executor | F1: Telefone | G1: Inicio | H1: Fim | I1: Tempo | J1: Status | O1: Rótulos de Linha | P1: Contagem de Atividade
A2: 5 | B2: INÍCIO CRQ | C2: IMPLANTACAOINFRATI_N2 | D2: REMOTO / DF | E2: FILIPE LIMA | F2: 61 98628-3620 | G2: 46053.785 | H2: =G2+I2 -> 46053.792 | I2: 0.0069444444 | J2: Concluído | O2: A Iniciar no prazo | P2: 7
A3: 10 | B3: STOP APLICAÇÃO SMARTCOPPER | C3: IMPLANTACAOINFRATI_N2 | D3: REMOTO / DF | E3: FILIPE LIMA | F3: 61 98628-3620 | G3: 46053.792 | H3: =G3+I3 -> 46053.854 | I3: 0.0625 | J3: Concluído | O3: N/A | P3: 1
A4: 15 | B4: DESMONTAR FS NFS NOS SERVIDORES IMPACTADOS | C4: STORAGE_N3 | D4: REMOTO / BH | E4: FREDERICO M CREPALDI | F4: 31 98758-6334 | G4: =H3 -> 46053.854 | H4: =G4+I4 -> 46053.896 | I4: 0.041666667 | J4: Concluído | K4: * EM CONJUNTO COM A SEQ 25 | O4: Concluído | P4: 6
A5: 15 | B5: REMOÇÃO DOS PVCS APONTANDO PARA O ANTIGO NFS (CRQ000000033493) | C5: INFRADIGITAL_N2 | D5: REMOTO / BH | E5: JOSE GERALDO | F5: 31 98773-7542 | G5: =H3 -> 46053.854 | H5: =G5+I5 -> 46053.896 | I5: 0.041666667 | J5: Concluído | O5: A Iniciar fora do prazo | P5: 2
A6: 20 | B6: SINCRONISMO NFS E REMOUNT DO NFS NOS SERVIDORES IMPACTADOS | C6: STORAGE_N3 | D6: REMOTO / BH | E6: EMIDIO MACEDO | F6: 31 98758-6334 | G6: =H5 -> 46053.896 | H6: =G6+I6 -> 46053.958 | I6: 0.0625 | J6: Concluído | K6: ** APÓS 22H HORAS ENVOLVER EMÍDIO | O6: Total Geral | P6: 16
A7: 20 | B7: CRIAÇÃO DOS PVCS APONTANDO PARA O NOVO NFS (CRQ000000033493) | C7: INFRADIGITAL_N2 | D7: REMOTO / BH | E7: JOSE GERALDO | F7: 31 98773-7542 | G7: =G6 -> 46053.896 | H7: =G7+I7 -> 46053.958 | I7: 0.0625 | J7: Concluído
A8: 30 | B8: AGUARDANDO EXECUÇÃO CRQ DE REDES (CRQ000000034373) | C8: REDES | D8: PRESENCIAL / RJ | E8: FRED POHL | F8: 31 98852-4355 | G8: =H7 -> 46053.958 | H8: =G8+I8 -> 46054.073 | I8: 0.11458333 | J8: Não executada - Rollback
A9: 35 | B9: START APLICAÇÃO SMARTCOPPER | C9: IMPLANTACAOINFRATI_N2 | D9: REMOTO / DF | E9: FILIPE LIMA | F9: 61 98628-3620 | G9: =H8 -> 46054.073 | H9: =G9+I9 -> 46054.115 | I9: 0.041666667 | J9: Não executada - Rollback
A10: 40 | B10: VALIDAR APLICAÇÃO SMARTCOPPER | C10: IMPLANTACAOINFRATI_N2 | D10: REMOTO / DF | E10: FILIPE LIMA | F10: 61 98628-3620 | G10: =H9 -> 46054.115 | H10: =G10+I10 -> 46054.156 | I10: 0.041666667 | J10: Não executada - Rollback
A11: ROLLBACK | J11: N/A
A12: 45 | B12: ATIVIDADE DE ROLLBACK - STOP APLICAÇÃO SMARTCOPPER | C12: IMPLANTACAOINFRATI_N2 | D12: REMOTO / DF | E12: FILIPE LIMA | F12: 61 98628-3620 | G12: =H10 -> 46054.156 | H12: =G12+I12 -> 46054.198 | I12: 0.041666667 | J12: Não executada - Rollback
A13: 50 | B13: ATIVIDADE DE ROLLBACK - DESMONTAR FS NFS NOS SERVIDORES IMPACTADOS | C13: STORAGE_N3 | D13: REMOTO / BH | E13: FREDERICO M CREPALDI | F13: 31 98758-6334 | G13: ='CRQ34373 - REDE'!H53 -> 46054.354 | H13: =G13+I13 -> 46054.396 | I13: 0.041666667 | J13: Concluído
A14: 55 | B14: ATIVIDADE DE ROLLBACK - REAPONTAMENTO E REMOUNT DO NFS NOS SERVIDORES IMPACTADOS | C14: STORAGE_N3 | D14: REMOTO / BH | E14: FREDERICO M CREPALDI | F14: 31 98758-6334 | G14: =H13 -> 46054.396 | H14: =G14+I14 -> 46054.437 | I14: 0.041666667 | J14: Concluído
A15: 60 | B15: ATIVIDADE DE ROLLBACK - REAPONTAMENTO DOS PVCS PARA O ANTIGO NFS | C15: INFRADIGITAL_N2 | D15: REMOTO / BH | E15: JOSE GERALDO | F15: 31 98773-7542 | G15: =H14 -> 46054.437 | H15: =G15+I15 -> 46054.479 | I15: 0.041666667 | J15: Concluído
A16: 65 | B16: ATIVIDADE DE ROLLBACK - START APLICAÇÃO SMARTCOPPER | C16: IMPLANTACAOINFRATI_N2 | D16: REMOTO / DF | E16: FILIPE LIMA | F16: 61 98628-3620 | G16: =H15 -> 46054.479 | H16: =G16+I16 -> 46054.521 | I16: 0.041666667 | J16: Concluído
A17: 70 | B17: ATIVIDADE DE ROLLBACK - VALIDAR APLICAÇÃO SMARTCOPPER | C17: IMPLANTACAOINFRATI_N2 | D17: REMOTO / DF | E17: FILIPE LIMA | F17: 61 98628-3620 | G17: =H16 -> 46054.521 | H17: =G17+I17 -> 46054.562 | I17: 0.041666667 | J17: Concluído
A18: 75 | B18: ENCERRAR CRQ | C18: IMPLANTACAOINFRATI_N2 | D18: REMOTO / DF | E18: FILIPE LIMA | F18: 61 98628-3620 | G18: =H17 -> 46054.562 | H18: =G18+I18 -> 46054.583 | I18: 0.020833333 | J18: Concluído

Sheet CRQ33459 - SI
A1: Seq | B1: Atividade | C1: Grupo | D1: Localidade | E1: Executor | F1: Telefone | G1: Inicio | H1: Fim | I1: Tempo | J1: Status
A2: 5 | B2: INÍCIO CRQ | C2: IMPLANTACAOINFRATI_N2 | D2: REMOTO / BH | E2: RENATO VIEIRA | F2: 31 97501-9451 | G2: 46053.535 | H2: =G2+I2 -> 46053.542 | I2: 0.0069444444 | J2: Concluído
A3: 10 | B3: START VMOTION DOS SERVIDORES COFRE DE SENHA | C3: UNIX_N2 | D3: REMOTO / BH | E3: FREDERICO M CREPALDI | F3: 31 98758-6334 | G3: =H2 -> 46053.542 | H3: =G3+I3 -> 46053.75 | I3: 0.20833333 | J3: Concluído | L3: Rótulos de Linha | M3: Contagem de Atividade
A4: 10 | B4: BACKUP FULL DOS ICS DA APP IDENTIDADE E COFRE DE CONTATO (EDIR) | C4: BACKUP_N1 | D4: REMOTO / DF | E4: ALEX B SOARES | F4: 61 98596-4456 | G4: =H2 -> 46053.542 | H4: =G4+I4 -> 46053.75 | I4: 0.20833333 | J4: Concluído | L4: A Iniciar no prazo | M4: 10
A5: 15 | B5: STOP DOS JOBS E CADEIAS CONTROL-M | C5: PCP_N2 | D5: REMOTO / DF | E5: SILAS DE OLIVEIRA | F5: 61 9844-91418 | G5: =H4 -> 46053.75 | H5: =G5+I5 -> 46053.792 | I5: 0.041666667 | J5: Concluído | L5: Concluído | M5: 13
A6: 15 | B6: STOP DAS ROTINAS DE BACKUP E JOBS CONTROL-M | C6: BACKUPIMPLANTACAO_N2 | D6: REMOTO / DF | E6: ALEX B SOARES | F6: 61 98596-4456 | G6: =H4 -> 46053.75 | H6: =G6+I6 -> 46053.792 | I6: 0.041666667 | J6: Concluído | K6: parar vms do Identidade | L6: Total Geral | M6: 23
