Workbook

Sheet Visao executiva CRQs 31jan

Sheet CRQ34373 - REDE
A1: Seq | B1: Atividade | C1: Grupo | D1: Localidade | E1: Executor | F1: Telefone | G1: Inicio | H1: Fim | I1: Tempo
A2: 5 | B2: INÍCIO CRQ | C2: IMPLANTACAOINFRATI_N2 | D2: REMOTO / BH | E2: RENATO D VIEIRA | F2: 31 98207-8920 | G2: 46053.535 | H2: =G2+I2 -> 46053.542 | I2: 0.0069444444
A3: 10 | B3: VALIDAÇÃO BACKUP DOS ICS RELACIONADOS | C3: BACKUPPLANEJAMENTO_N2 | D3: REMOTO / DF | E3: RAFAEL SOUSA | F3: 61 98497-4792 | G3: =H2 -> 46053.542 | H3: =G3+I3 -> 46053.708 | I3: 0.16666667 | L3: Rótulos de Linha | M3: Contagem de Atividade
A4: 15 | B4: STOP DOS JOBS E CADEIAS CONTROL-M PRODUÇÃO | C4: PCP_N2 | D4: REMOTO / DF | E4: SILAS DE OLIVEIRA | F4: 61 9844-91418 | G4: =H3 -> 46053.708 | H4: =G4+I4 -> 46053.75 | I4: 0.041666667 | L4: A Iniciar fora prazo | M4: 69
A5: 15 | B5: STOP DOS JOBS E CADEIAS CONTROL-M BACKUP | C5: BACKUPPLANEJAMENTO_N2 | D5: REMOTO / DF | E5: RAFAEL SOUSA | F5: 61 98497-4792 | G5: =H3 -> 46053.708 | H5: =G5+I5 -> 46053.75 | I5: 0.041666667 | L5: N/A | M5: 5
A6: 18 | B6: REALIZAR BACKUP DOS ELEMENTOS DE REDE | C6: REDES | D6: PRESENCIAL / RJ | E6: FRED POLH | F6: 31 98852-4355 | G6: =H5 -> 46053.75 | H6: =G6+I6 -> 46053.792 | I6: 0.041666667 | L6: Total Geral | M6: 74
A7: 18 | B7: STOP DA APLICAÇÃO SOM/OMR | C7: SOM_N2 | D7: REMOTO / DF | E7: DIONEY YANO | F7: 61 98466-4590 | G7: =H6 -> 46053.792 | H7: =G7+I7 -> 46053.833 | I7: 0.041666667
A8: 19 | B8: STOP DA APLICAÇÃO SIS ATIVAÇÃO/NETQ | C8: SISATIVACAOFIXA_N2 | D8: REMOTO / DF | E8: ARSENIO SANTOS | F8: 61 98665-4644 | G8: =H6 -> 46053.792 | H8: =G8+I8 -> 46053.833 | I8: 0.041666667
A9: 19 | B9: STOP DA APLICAÇÃO SOA | C9: INTEGRACAO_N2 | D9: REMOTO / DF | E9: LEANDRO CONTE | F9: 61 98595-4649 | G9: =H6 -> 46053.792 | H9: =G9+I9 -> 46053.833 | I9: 0.041666667
A10: 19 | B10: STOP DA APLICAÇÃO NETWIN | C10: NETWIN_N2 | D10: REMOTO / DF | E10: DANIEL PRAXEDES | F10: 61 98491-6039 | G10: =H6 -> 46053.792 | H10: =G10+I10 -> 46053.833 | I10: 0.041666667
A11: 19 | B11: STOP DA APLICAÇÃO GCP | C11: JORNADAL2O_N2 | D11: REMOTO / RJ | E11: ALEX OREM | F11: 21 98528- 5400 | G11: =H6 -> 46053.792 | H11: =G11+I11 -> 46053.833 | I11: 0.041666667
A12: 20 | B12: STOP DO BDs e GRID que NÃO serão migrados das aplicações acima | C12: ORACLE_N2 | D12: REMOTO /BH | E12: LUIZ PUNTEL | F12: 31 98758-7194 | G12: =H11 -> 46053.833 | H12: =G12+I12 -> 46053.917 | I12: 0.083333333
A13: 19 | B13: CRQ SI | D13: REMOTO / DF | E13: ROMANO GOMES | F13: 61 98574-9927 | G13: ='CRQ33459 - SI'!G7 -> 46053.792 | H13: ='CRQ33459 - SI'!H14 -> 46053.958
A14: 19 | B14: CRQ Openshift | D14: REMOTO / BH | E14: RENATO D VIEIRA | F14: 31 98207-8920 | G14: ='CRQ033493 - OPENSHIFT'!G6 -> 46053.792 | H14: ='CRQ033493 - OPENSHIFT'!H14 -> 46053.958
A15: 19 | B15: CRQ NAS | D15: REMOTO / DF | E15: FILIPE LIMA | F15: 61 98628-3620 | G15: ='CRQ34463 - NFS'!G2 -> 46053.785 | H15: ='CRQ34463 - NFS'!H7 -> 46053.958
A16: 21 | B16: REALIZAR MIGRAÇÃO DA VLANS PARA O DC ARCOS | C16: REDES | D16: PRESENCIAL / RJ | E16: FRED POLH | F16: 31 98852-4355 | G16: =H13 -> 46053.958 | H16: =G16+I16 -> 46054.073 | I16: 0.11458333
A17: 27 | B17: START DOS BDs .....(add as outras aplicações) | C17: ORACLE_N2 | D17: REMOTO / BH | E17: LUIZ PUNTEL | F17: 31 98758-7194 | G17: =H16 -> 46054.073 | H17: =G17+I17 -> 46054.115 | I17: 0.041666667
A18: 27 | B18: Validar TODAS as outras aplicações | C18: JORNADAFULF_N2 | D18: REMOTO / DF | E18: DIEGO ARCANJO | F18: 61 98679-4930 | G18: =H16 -> 46054.073 | H18: =G18+I18 -> 46054.115 | I18: 0.041666667
A19: 27 | B19: Validar TODAS as outras aplicações | C19: JORNADAL2O_N2 | D19: REMOTO / DF | E19: MARCIO ROBERTO | F19: 61 98409-4671 | G19: =H16 -> 46054.073 | H19: =G19+I19 -> 46054.115 | I19: 0.041666667
A20: 27 | B20: Validar TODAS aplicações (Ewerson) | C20: JORNADACORP_N2 | D20: REMOTO / RJ | E20: ROBERTO REBEQUE | F20: 21 98834-3136 | G20: =H16 -> 46054.073 | H20: =G20+I20 -> 46054.115 | I20: 0.041666667
A21: 27 | B21: Validar ITSM | C21: ITSM_N2 | D21: REMOTO / DF | E21: TASSIO COSTA | F21: 61 98618-0128 | G21: =H16 -> 46054.073 | H21: =G21+I21 -> 46054.115 | I21: 0.041666667
A22: 27 | B22: Validar Monitoração | C22: MONITORACAO_N2 | D22: REMOTO / TO | E22: JOSE FRANCISCO KLAUS | F22: 48 99988-0876 | G22: =H16 -> 46054.073 | H22: =G22+I22 -> 46054.115 | I22: 0.041666667
A23: 27 | B23: Validar CMDB | C23: CMDB_N2 | D23: REMOTO / PR | E23: RAFAEL DEMBICKI | F23: 41 99145- 3635 | G23: =H16 -> 46054.073 | H23: =G23+I23 -> 46054.115 | I23: 0.041666667
A24: 27 | B24: Validar aplicações SI | C24: IDDIGITAL_N2 | D24: REMOTO / DF | E24: ROMANO GOMES | F24: 61 985749927 | G24: =H16 -> 46054.073 | H24: =G24+I24 -> 46054.115 | I24: 0.041666667
A25: 27 | B25: Validar aplicações SI (COPS) | C25: SOC_N2 | D25: REMOTO / RJ | E25: MARCELO MONTEZUMA | F25: 21 98864-0464 | G25: =H16 -> 46054.073 | H25: =G25+I25 -> 46054.115 | I25: 0.041666667
A26: 28 | B26: START DA APLICAÇÃO SIS ATIVAÇÃO/ NETQ | C26: SISATIVACAOFIXA_N2 | D26: REMOTO / DF | E26: ARSENIO SANTOS | F26: 61 98665-4644 | G26: =H17 -> 46054.115 | H26: =G26+I26 -> 46054.156 | I26: 0.041666667
A27: 28 | B27: START DA APLICAÇÃO SOA | C27: INTEGRACAO_N2 | D27: REMOTO / DF | E27: LEANDRO CONTE | F27: 61 98595-4649 | G27: =H17 -> 46054.115 | H27: =G27+I27 -> 46054.156 | I27: 0.041666667
A28: 28 | B28: START DA APLICAÇÃO NETWIN | C28: NETWIN_N2 | D28: REMOTO / DF | E28: DANIEL PRAXEDES | F28: 61 98491-6039 | G28: =H17 -> 46054.115 | H28: =G28+I28 -> 46054.156 | I28: 0.041666667
A29: 28 | B29: START DA APLICAÇÃO GCP | C29: JORNADAL2O_N2 | D29: REMOTO / RJ | E29: ALEX OREM | F29: 21 98528- 5400 | G29: =H17 -> 46054.115 | H29: =G29+I29 -> 46054.156 | I29: 0.041666667
A30: 28 | B30: Validar TODAS as outras aplicações | C30: JORNADAFULF_N2 | D30: REMOTO / DF | E30: DIEGO ARCANJO | F30: 61 98679-4930 | G30: =H25 -> 46054.115 | H30: =G30+I30 -> 46054.156 | I30: 0.041666667
A31: 28 | B31: Validar TODAS as outras aplicações | C31: JORNADAL2O_N2 | D31: REMOTO / DF | E31: MARCIO ROBERTO | F31: 61 98409-4671 | G31: =H25 -> 46054.115 | H31: =G31+I31 -> 46054.156 | I31: 0.041666667
A32: 28 | B32: Validar Monitoração | C32: MONITORACAO_N2 | D32: REMOTO / TO | E32: JOSE FRANCISCO KLAUS | F32: 48 99988-0876 | G32: =H25 -> 46054.115 | H32: =G32+I32 -> 46054.156 | I32: 0.041666667
A33: 28 | B33: Validar CMDB | C33: CMDB_N2 | D33: REMOTO / PR | E33: RAFAEL DEMBICKI | F33: 41 99145- 3635 | G33: =H25 -> 46054.115 | H33: =G33+I33 -> 46054.156 | I33: 0.041666667
A34: 28 | B34: Validar aplicações SI | C34: IDDIGITAL_N2 | D34: REMOTO / DF | E34: ROMANO GOMES | F34: 61 985749927 | G34: =H25 -> 46054.115 | H34: =G34+I34 -> 46054.156 | I34: 0.041666667
A35: 29 | B35: START DA APLICAÇÃO SOM/OMR | C35: SOM_N2 | D35: REMOTO / DF | E35: DIONEY YANO | F35: 61 98466-4590 | G35: =H28 -> 46054.156 | H35: =G35+I35 -> 46054.198 | I35: 0.041666667
A36: 30 | B36: VALIDAR APLICAÇÃO SIS ATIVAÇÃO/NETQ | C36: SISATIVACAOFIXA_N2 | D36: REMOTO / DF | E36: ARSENIO SANTOS | F36: 61 98665-4644 | G36: =H35 -> 46054.198 | H36: =G36+I36 -> 46054.281 | I36: 0.083333333
A37: 30 | B37: VALIDAR SOA | C37: INTEGRACAO_N2 | D37: REMOTO / DF | E37: LEANDRO CONTE | F37: 61 98595-4649 | G37: =H35 -> 46054.198 | H37: =G37+I37 -> 46054.281 | I37: 0.083333333
A38: 30 | B38: VALIDAR NETWIN | C38: NETWIN_N2 | D38: REMOTO / DF | E38: DANIEL PRAXEDES | F38: 61 98491-6039 | G38: =H35 -> 46054.198 | H38: =G38+I38 -> 46054.281 | I38: 0.083333333
A39: 30 | B39: VALIDAR SOM/OMR | C39: SOM_N2 | D39: REMOTO / DF | E39: DIONEY YANO | F39: 61 98466-4590 | G39: =H35 -> 46054.198 | H39: =G39+I39 -> 46054.281 | I39: 0.083333333
A40: 30 | B40: VALIDAR GCP | C40: JORNADAL2O_N2 | D40: REMOTO / RJ | E40: ALEX OREM | F40: 21 98528- 5400 | G40: =H35 -> 46054.198 | H40: =G40+I40 -> 46054.281 | I40: 0.083333333
...

Sheet CRQ033493 - OPENSHIFT
A1: Seq | B1: Atividade | C1: Grupo | D1: localidade | E1: Executor | F1: Telefone | G1: Inicio | H1: Fim | I1: Tempo | L1: PORTAL OPERACIONAL - PCW - PRD
A2: 5 | B2: INÍCIO CRQ | C2: IMPLANTACAOINFRATI_N2 | D2: REMOTO / BH | E2: RENATO VIEIRA | F2: 31 97501-9451 | G2: 46053.701 | H2: =G2+I2 -> 46053.708 | I2: 0.0069444444 | L2: [VTAL] GEOSITE - PRD
A3: 10 | B3: BACKUP FULL DOS ICS RELACIONADOS | C3: BACKUPPLANEJAMENTO_N2 | D3: REMOTO / DF | E3: ALEX B SOARES | F3: 61 98596-4456 | G3: =H2 -> 46053.708 | H3: =G3+I3 -> 46053.75 | I3: 0.041666667 | L3: GEOSITE LOGRADOURO - PRD | N3: Rótulos de Linha | O3: Total
A4: 15 | B4: STOP DOS JOBS E CADEIAS CONTROL-M | C4: PCP_N2 | D4: REMOTO / DF | E4: SILAS DE OLIVEIRA | F4: 61 9844-91418 | G4: =H3 -> 46053.75 | H4: =G4+I4 -> 46053.792 | I4: 0.041666667 | L4: MICROSSERVICOS CW - PRD | N4: A Iniciar no prazo | O4: 30
A5: 15 | B5: STOP DAS ROTINAS DE BACKUP E JOBS CONTROL-M | C5: BACKUPPLANEJAMENTO_N2 | D5: REMOTO / DF | E5: ALEX B SOARES | F5: 61 98596-4456 | G5: =H3 -> 46053.75 | H5: =G5+I5 -> 46053.792 | I5: 0.041666667 | L5: MS ORDER ENTRY - PRD | N5: A Iniciar fora prazo | O5: 1
A6: 18 | B6: PARAR APLICAÇÕES (ARCOS E SCN PRD) | C6: INFRADIGITAL_N2 | D6: REMOTO / BH | E6: JOSE GERALDO | F6: 31 98773-7542 | G6: 46053.792 | H6: =G6+I6 -> 46053.854 | I6: 0.0625 | L6: MS-COBRANÇA - PRD + MSCGNAT (Openshift) | N6: N/A | O6: 2
A7: 20 | B7: CONFIGURAÇÕES DO DNS/ROTAS OPENSHIFT | C7: INFRADIGITAL_N2 | D7: REMOTO / BH | E7: JOSE GERALDO | F7: 31 98773-7542 | G7: =H6 -> 46053.854 | H7: =G7+I7 -> 46053.917 | I7: 0.0625 | L7: ms-fuzzy-availability-check - PRD | N7: Total Geral | O7: 33
A8: 20 | B8: AJUSTAR ALIAS DNS PARA OS NOVOS SERVIDORES | C8: WINDOWS_N2 | D8: REMOTO / BH | E8: GLADYSTON | F8: 31 98877-9940 | G8: =H6 -> 46053.854 | H8: =G8+I8 -> 46053.917 | I8: 0.0625
A9: 20 | B9: EXECUTAR VIRADA DE PRODUÇÃO PARA ARCOS | C9: ORACLE_N2 | D9: REMOTO / BH | E9: LUIZ PUNTEL | F9: 31 98758-7194 | G9: =H6 -> 46053.854 | H9: =G9+I9 -> 46053.917 | I9: 0.0625 | L9: Incluir os nomes dos BDs a serem migrados
A10: 20 | B10: MIGRAÇÃO DOS ICS RELACIONADOS | C10: UNIX_N2 | D10: REMOTO / BH | E10: FREDERICO M CREPALDI | F10: 31 98758-6334 | G10: =H6 -> 46053.854 | H10: =G10+I10 -> 46053.917 | I10: 0.0625
A11: 20 | B11: MONITORAR GUARDICORE NOS SERVIDORES | C11: SEGSDI_N2 | D11: REMOTO / SP | E11: TIAGO FERREIRA CAMPOS | F11: 11 98268-7112 | G11: =H6 -> 46053.854 | H11: =G11+I11 -> 46053.917 | I11: 0.0625
A12: 25 | B12: STOP dos BDs | C12: ORACLE_N2 | D12: REMOTO / BH | E12: LUIZ PUNTEL | F12: 31 98758-7194 | G12: =H8 -> 46053.917 | H12: =G12+I12 -> 46053.979 | I12: 0.0625 | L12: Incluir os nomes dos BDs a serem migrados
A13: 26 | B13: REMOÇÃO DOS PVCS APONTANDO PARA O ANTIGO NFS | C13: INFRADIGITAL_N2 | D13: REMOTO / BH | E13: JOSE GERALDO | F13: 31 98773-7542 | G13: =H10 -> 46053.917 | H13: =G13+I13 -> 46053.958 | I13: 0.041666667
A14: 26 | B14: CRIAÇÃO DOS PVCS APONTANDO PARA O NOVO NFS | C14: INFRADIGITAL_N2 | D14: REMOTO / BH | E14: JOSE GERALDO | F14: 31 98773-7542 | G14: =H10 -> 46053.917 | H14: =G14+I14 -> 46053.958 | I14: 0.041666667
B15: CRQ NFS | D15: REMOTO / DF | E15: FILIPE LIMA | F15: 61 98628-3620 | G15: =H6 -> 46053.854 | H15: =G15+I15 -> 46053.979 | I15: 0.125
B16: VIRADA da REDE | D16: PRESENCIAL / RJ | E16: FRED POLH | F16: 31 98852-4355 | G16: ='CRQ34373 - REDE'!G16 -> 46053.958 | H16: ='CRQ34373 - REDE'!H16 -> 46054.073
A17: 28 | B17: SUBIR APLICAÇÃO (ARCOS PRD) DOS MICROSERVIÇOS | C17: INFRADIGITAL_N2 | D17: REMOTO / BH | E17: JOSE GERALDO | F17: 31 98773-7542 | G17: =H16 -> 46054.073 | H17: =G17+I17 -> 46054.167 | I17: 0.09375
A18: 30 | B18: VALIDAR APLICAÇÃO | C18: JORNADAL2O_N2 | D18: REMOTO / RJ | E18: ALEXANDRE ARCOVERDE | F18: 21 98606-3088 | G18: =H17 -> 46054.167 | H18: =G18+I18 -> 46054.333 | I18: 0.16666667
A19: 30 | B19: VALIDAR APLICAÇÃO | C19: JORNADAFULF_N2 | D19: REMOTO / SP | E19: MICHAEL D SILVA | F19: 19 98349-4052 | G19: =H17 -> 46054.167 | H19: =G19+I19 -> 46054.333 | I19: 0.16666667
A20: 30 | B20: VALIDAR APLICAÇÃO PELA ÁREA USUÁRIA | E20: ??? | G20: =H17 -> 46054.167 | H20: =G20+I20 -> 46054.333 | I20: 0.16666667
A21: 35 | B21: LIBERAR ROTINAS DE BACKUP E JOBS CONTROL-M | C21: BACKUPPLANEJAMENTO_N2 | D21: REMOTO / DF | E21: RAFAEL SOUSA | F21: 61 98497-4792 | G21: =H20 -> 46054.333 | H21: =G21+I21 -> 46054.375 | I21: 0.041666667
A22: 35 | B22: RETIRAR DE HOLD JOBS E CADEIAS CONTROL-M | C22: PCP_N2 | D22: REMOTO / DF | E22: ROBERTO MAIA | F22: 61 98427-5240 | G22: =H20 -> 46054.333 | H22: =G22+I22 -> 46054.375 | I22: 0.041666667
A23: 60 | B23: ENCERRAR CRQ | C23: IMPLANTACAOINFRATI_N2 | D23: REMOTO / BH | E23: RENATO D VIEIRA | F23: 31 98207-8920 | G23: =H22 -> 46054.375 | H23: =G23+I23 -> 46054.396 | I23: 0.020833333

Sheet CRQ34463 - NFS
A1: Seq | B1: Atividade | C1: Grupo | D1: localidade | E1: Executor | F1: Telefone | G1: Inicio | H1: Fim | I1: Tempo | O1: Rótulos de Linha | P1: Contagem de Atividade
A2: 5 | B2: INÍCIO CRQ | C2: IMPLANTACAOINFRATI_N2 | D2: REMOTO / DF | E2: FILIPE LIMA | F2: 61 98628-3620 | G2: 46053.785 | H2: =G2+I2 -> 46053.792 | I2: 0.0069444444 | O2: A Iniciar fora prazo | P2: 14
A3: 10 | B3: STOP APLICAÇÃO SMARTCOPPER | C3: IMPLANTACAOINFRATI_N2 | D3: REMOTO / DF | E3: FILIPE LIMA | F3: 61 98628-3620 | G3: 46053.792 | H3: =G3+I3 -> 46053.854 | I3: 0.0625 | O3: N/A | P3: 1
A4: 15 | B4: DESMONTAR FS NFS NOS SERVIDORES IMPACTADOS | C4: STORAGE_N3 | D4: REMOTO / BH | E4: FREDERICO M CREPALDI | F4: 31 98758-6334 | G4: =H3 -> 46053.854 | H4: =G4+I4 -> 46053.896 | I4: 0.041666667 | K4: * EM CONJUNTO COM A SEQ 25 | O4: Em execução no prazo | P4: 1
A5: 15 | B5: REMOÇÃO DOS PVCS APONTANDO PARA O ANTIGO NFS (CRQ000000033493) | C5: INFRADIGITAL_N2 | D5: REMOTO / BH | E5: JOSE GERALDO | F5: 31 98773-7542 | G5: =G4 -> 46053.854 | H5: =G5+I5 -> 46053.896 | I5: 0.041666667 | O5: Total Geral | P5: 16
A6: 20 | B6: SINCRONISMO NFS E REMOUNT DO NFS NOS SERVIDORES IMPACTADOS | C6: STORAGE_N3 | D6: REMOTO / BH | E6: FREDERICO M CREPALDI | F6: 31 98758-6334 | G6: =H4 -> 46053.896 | H6: =G6+I6 -> 46053.958 | I6: 0.0625 | K6: ** APÓS 22H HORAS ENVOLVER EMÍDIO
A7: 20 | B7: CRIAÇÃO DOS PVCS APONTANDO PARA O NOVO NFS (CRQ000000033493) | C7: INFRADIGITAL_N2 | D7: REMOTO / BH | E7: JOSE GERALDO | F7: 31 98773-7542 | G7: =G6 -> 46053.896 | H7: =H6 -> 46053.958 | I7: 0.041666667
A8: 30 | B8: AGUARDANDO EXECUÇÃO CRQ DE REDES (CRQ000000034373) | C8: REDES | D8: PRESENCIAL / RJ | E8: FRED POHL | F8: 31 98852-4355 | G8: =H7 -> 46053.958 | H8: =G8+I8 -> 46054.073 | I8: 0.11458333
A9: 35 | B9: START APLICAÇÃO SMARTCOPPER | C9: IMPLANTACAOINFRATI_N2 | D9: REMOTO / DF | E9: FILIPE LIMA | F9: 61 98628-3620 | G9: =H8 -> 46054.073 | H9: =G9+I9 -> 46054.115 | I9: 0.041666667
A10: 40 | B10: VALIDAR APLICAÇÃO SMARTCOPPER | C10: IMPLANTACAOINFRATI_N2 | D10: REMOTO / DF | E10: FILIPE LIMA | F10: 61 98628-3620 | G10: =H9 -> 46054.115 | H10: =G10+I10 -> 46054.156 | I10: 0.041666667
A11: 75 | B11: ENCERRAR CRQ | C11: IMPLANTACAOINFRATI_N2 | D11: REMOTO / DF | E11: FILIPE LIMA | F11: 61 98628-3620 | G11: =H10 -> 46054.156 | H11: =G11+I11 -> 46054.177 | I11: 0.020833333

Sheet CRQ33459 - SI
A1: Seq | B1: Atividade | C1: Grupo | D1: Localidade | E1: Executor | F1: Telefone | G1: Inicio | H1: Fim | I1: Tempo
A2: 5 | B2: INÍCIO CRQ | C2: IMPLANTACAOINFRATI_N2 | D2: REMOTO / BH | E2: RENATO VIEIRA | F2: 31 97501-9451 | G2: 46053.535 | H2: =G2+I2 -> 46053.542 | I2: 0.0069444444
A3: 10 | B3: START VMOTION DOS SERVIDORES COFRE DE SENHA | C3: UNIX_N2 | D3: REMOTO / BH | E3: FREDERICO M CREPALDI | F3: 31 98758-6334 | G3: =H2 -> 46053.542 | H3: =G3+I3 -> 46053.562 | I3: 0.020833333 | L3: Rótulos de Linha | M3: Contagem de Atividade
A4: 10 | B4: BACKUP FULL DOS ICS DA APP IDENTIDADE E COFRE DE CONTATO (EDIR) | C4: BACKUP_N1 | D4: REMOTO / DF | E4: ALEX B SOARES | F4: 61 98596-4456 | G4: =H2 -> 46053.542 | H4: =G4+I4 -> 46053.75 | I4: 0.20833333 | L4: A Iniciar fora prazo | M4: 25
A5: 15 | B5: STOP DOS JOBS E CADEIAS CONTROL-M | C5: PCP_N2 | D5: REMOTO / DF | E5: SILAS DE OLIVEIRA | F5: 61 9844-91418 | G5: =H4 -> 46053.75 | H5: =G5+I5 -> 46053.792 | I5: 0.041666667 | L5: Total Geral | M5: 25
A6: 15 | B6: STOP DAS ROTINAS DE BACKUP E JOBS CONTROL-M | C6: BACKUPIMPLANTACAO_N2 | D6: REMOTO / DF | E6: ALEX B SOARES | F6: 61 98596-4456 | G6: =H4 -> 46053.75 | H6: =G6+I6 -> 46053.792 | I6: 0.041666667 | K6: parar vms do Identidade
A7: 20 | B7: PARAR APLICAÇÕES Identidade e cofre de contato | C7: IDDIGITAL_N2 | D7: REMOTO / DF | E7: ROMANO GOMES | F7: 61985749927 | G7: 46053.792 | H7: =G7+I7 -> 46053.833 | I7: 0.041666667
A8: 25 | B8: AJUSTAR ALIAS DNS PARA OS NOVOS SERVIDORES | C8: WINDOWS_N2 | D8: REMOTO / BH | E8: GLADYSTON | F8: 31 98877-9940 | G8: =H7 -> 46053.833 | H8: =G8+I8 -> 46053.875 | I8: 0.041666667
A9: 25 | B9: EXECUTAR VIRADA DE PRODUÇÃO PARA ARCOS | C9: ORACLE_N2 | D9: REMOTO / BH | E9: LUIZ PUNTEL | F9: 31 98758-7194 | G9: =H7 -> 46053.833 | H9: =G9+I9 -> 46053.875 | I9: 0.041666667
A10: 25 | B10: DESLIGAR ICS RELACIONADOS | C10: UNIX_N2 | D10: REMOTO / BH | E10: FREDERICO M CREPALDI | F10: 31 98758-6334 | G10: =H7 -> 46053.833 | H10: =G10+I10 -> 46053.875 | I10: 0.041666667
A11: 25 | B11: MIGRAÇÃO DOS ICS RELACIONADOS | C11: UNIX_N2 | D11: REMOTO / BH | E11: FREDERICO M CREPALDI | F11: 31 98758-6334 | G11: =H7 -> 46053.833 | H11: =G11+I11 -> 46053.875 | I11: 0.041666667
A12: 25 | B12: MONITORAR GUARDICORE NOS SERVIDORES | C12: SEGSDI_N2 | D12: REMOTO / SP | E12: TIAGO FERREIRA CAMPOS | F12: 11 98268-7112 | G12: =H7 -> 46053.833 | H12: =G12+I12 -> 46053.875 | I12: 0.041666667
A13: 28 | B13: SUBIR APLICAÇÃO Identidade e cofre de contato | C13: IDDIGITAL_N2 | D13: REMOTO / DF | E13: ROMANO GOMES | F13: 61985749927 | G13: =H11 -> 46053.875 | H13: =G13+I13 -> 46053.917 | I13: 0.041666667
A14: 30 | B14: VALIDAR APLICAÇÃO | C14: IDDIGITAL_N2 | D14: REMOTO / DF | E14: ROMANO GOMES | F14: 61985749927 | G14: =H13 -> 46053.917 | H14: =G14+I14 -> 46053.958 | I14: 0.041666667
A15: 35 | B15: LIBERAR ROTINAS DE BACKUP E JOBS CONTROL-M | C15: BACKUPIMPLANTACAO_N2 | D15: REMOTO / DF | E15: RAFAEL SOUSA | F15: 61 98497-4792 | G15: =H14 -> 46053.958 | H15: =G15+I15 -> 46054 | I15: 0.041666667
A16: 35 | B16: RETIRAR DE HOLD JOBS E CADEIAS CONTROL-M | C16: PCP_N2 | D16: REMOTO / DF | E16: ROBERTO MAIA | F16: 61 98427-5240 | G16: =H14 -> 46053.958 | H16: =G16+I16 -> 46054 | I16: 0.041666667
A17: 60 | B17: ENCERRAR CRQ | C17: IMPLANTACAOINFRATI_N2 | D17: REMOTO / BH | E17: THASIO FAZENDEIRO | F17: 31 97501-9451 | G17: =H16 -> 46054 | H17: =G17+I17 -> 46054.021 | I17: 0.020833333
B21: CARKPW01A | C21: COFRE DE SENHAS - PRD
B22: CARKPW02 | C22: COFRE DE SENHAS - PRD
B23: CARKPW03 | C23: COFRE DE SENHAS - PRD
B24: CARKPX01 | C24: COFRE DE SENHAS - PRD
B25: CARKPX02 | C25: COFRE DE SENHAS - PRD
B26: CARKPX03 | C26: COFRE DE SENHAS - PRD
B27: CARKPX04A | C27: COFRE DE SENHAS - PRD
B28: CARKPX04B | C28: COFRE DE SENHAS - PRD

Sheet Planilha3
A1: MS-COBRANÇA
A2: [VTAL] GEOSITE
A3: GEOSITE LOGRADOURO
A4: MS-FUZZY-AVAILABILITY-CHECK
A5: MS ORDER ENTRY
A6: microserviço de consulta de viabilidade de mudança de viabilidade, CHINESE WALL
A7: PORTAL OPERACIONAL - PCW
A8: MS-EVENTMANAGEMENT
A9: MS-POTARA-LOGRADOURO
A10: MICROSSERVICOS CW

Sheet Atividades (2)
A1: Seq | B1: Atividade | C1: Grupo | D1: Executor | E1: Inicio | F1: Fim | G1: Observação
A2: 5 | B2: INÍCIO CRQ | C2: IMPLANTACAOINFRATI_N2 | D2: RENATO D VIEIRA | E2: 46011.785 | F2: 46011.792
A3: 10 | B3: BACKUP FULL DOS ICS RELACIONADOS | C3: BACKUP_N1 | D3: RAFAEL M SOUSA | E3: 46011.792 | F3: 46011.875
A4: 15 | B4: STOP DOS JOBS E CADEIAS CONTROL-M | C4: PCP_N2 | D4: ROBERTO C MAIA | E4: 46011.875 | F4: 46011.917
A5: 15 | B5: STOP DAS ROTINAS DE BACKUP E JOBS CONTROL-M | C5: BACKUPIMPLANTACAO_N2 | D5: RAFAEL M SOUSA | E5: 46011.875 | F5: 46011.917
A6: 18 | B6: STOP DA APLICAÇÃO | C6: SISATIVACAOFIXA_N2 | D6: ARSENIO | E6: 46011.917 | F6: 45677.958 | G6: tentar parar às 20hs
A7: 25 | B7: AJUSTAR ALIAS DNS PARA OS NOVOS SERVIDORES | C7: UNIX_N2 | D7: FREDERICO M CREPALDI | E7: 45677.958 | F7: 46012.062
A8: 25 | B8: REALIZAR ALTERAÇÃO DO DNS E ROTA | C8: INFRADIGITAL_N2 | D8: THIAGO ROCHAEL | E8: 45677.958 | F8: 46012.062
A9: 25 | B9: EXECUTAR VIRADA DE PRODUÇÃO PARA ARCOS | C9: ORACLE_N2 | D9: LUIZ F PUNTEL | E9: 45677.958 | F9: 46012.062
A10: 25 | B10: DESLIGAR ICS RELACIONADOS | C10: UNIX_N2 | D10: FREDERICO M CREPALDI | E10: 45677.958 | F10: 46012.062
A11: 25 | B11: MIGRAÇÃO DOS ICS RELACIONADOS | C11: UNIX_N2 | D11: FREDERICO M CREPALDI | E11: 45677.958 | F11: 46012.062
A12: 28 | B12: START DA APLICAÇÃO | C12: SISATIVACAOFIXA_N2 | D12: ARSENIO | E12: 46012.062 | F12: 46012.104
A13: 29 | B13: AJUSTAR CONFIGMAP DO cgnat-management-api e microservicososs-cobranca-prod | C13: INFRADIGITAL_N2 | D13: THIAGO ROCHAEL | E13: 46012.104 | F13: 46012.125
A14: 30 | B14: VALIDAR APLICAÇÃO SIS | C14: SISATIVACAOFIXA_N2 | D14: ARSENIO | E14: 46012.125 | F14: 46012.208
A15: 30 | B15: VALIDAR SOA/APROVISIONADOR | C15: INTEGRACAO_N2 | D15: SANDRO GONTIJO | E15: 46012.125 | F15: 46012.208
A16: 30 | B16: VALIDAR MS COBRANÇA | C16: MS Cobrança N2 | D16: MICHAEL DOUGLAS | E16: 46012.125 | F16: 46012.208
A17: 30 | B17: VALIDAR SOM/OMR | C17: SOM_N2 | D17: RELRYSON | E17: 46012.125 | F17: 46012.208
A18: 35 | B18: LIBERAR ROTINAS DE BACKUP E JOBS CONTROL-M | C18: BACKUPIMPLANTACAO_N2 | D18: WESLEY M RODRIGUES | E18: 46012.208 | F18: 46012.229
A19: 35 | B19: RETIRAR DE HOLD JOBS E CADEIAS CONTROL-M | C19: PCP_N2 | D19: ROBERTO C MAIA | E19: 46012.208 | F19: 46012.229
A20: ROLLBACK
A21: 38 | B21: ATIVIDADE DE ROLLBACK - STOP DA APLICAÇÃO | C21: SISATIVACAOFIXA_N2 | D21: RODRIGO F MAIA | E21: 46012.208 | F21: 46012.25
A22: 45 | B22: ATIVIDADE DE ROLLBACK - AJUSTAR ALIAS DNS | C22: UNIX_N2 | D22: FREDERICO M CREPALDI | E22: 46012.25 | F22: 46012.292
A23: 45 | B23: ATIVIDADE DE ROLLBACK - DESLIGAR SERVIDORES E RELIGAR NA ORIGEM | C23: UNIX_N2 | D23: FREDERICO M CREPALDI | E23: 46012.25 | F23: 46012.292
A24: 45 | B24: ATIVIDADE DE ROLLBACK - EXECUTAR VIRADA DE PRODUÇÃO PARA SCN | C24: ORACLE_N2 | D24: LUIZ F PUNTEL | E24: 46012.25 | F24: 46012.292
A25: 45 | B25: ATIVIDADE DE ROLLBACK - REALIZAR ALTERAÇÃO DO DNS E ROTA | C25: INFRADIGITAL_N2 | D25: JOSE G FURTADO | E25: 46012.25 | F25: 46012.292
A26: 48 | B26: ATIVIDADE DE ROLLBACK - START DA APLICAÇÃO | C26: SISATIVACAOFIXA_N2 | D26: ARSENIO | E26: 46012.292 | F26: 46012.333
A27: 49 | B27: ATIVIDADE DE ROLLBACK - DO CONFIGMAP cgnat-management-api e microservicososs-cobranca-prod | C27: INFRADIGITAL_N2 | D27: JOSE G FURTADO | E27: 46012.333 | F27: 46012.375
A28: 50 | B28: ATIVIDADE DE ROLLBACK - VALIDAR APLICAÇÃO SIS | C28: SISATIVACAOFIXA_N2 | D28: RODRIGO F MAIA | E28: 46012.375 | F28: 46012.417
A29: 50 | B29: VALIDAR SOA/APROVISIONADOR | C29: INTEGRACAO_N2 | D29: SANDRO GONTIJO | E29: 46012.375 | F29: 46012.417
A30: 50 | B30: VALIDAR MS COBRANÇA | C30: MS Cobrança N2 | D30: MICHAEL DOUGLAS | E30: 46012.375 | F30: 46012.417
A31: 50 | B31: VALIDAR SOM/OMR | C31: SOM_N2 | D31: RELRYSON | E31: 46012.375 | F31: 46012.417
A32: 55 | B32: ATIVIDADE DE ROLLBACK - RETIRAR DE HOLD JOBS E CADEIAS CONTROL-M | C32: PCP_N2 | D32: ROBERTO C MAIA | E32: 46012.417 | F32: 46012.438
... A34: 60 | B34: ENCERRAR CRQ | C34: IMPLANTACAOINFRATI_N2 | D34: RENATO D VIEIRA | E34: 46012.438 | F34: 46012.458
